Workbook

Sheet gemini-3.1-pro-preview
A1: pdf_id | B1: model | C1: llm_document_type | D1: llm_model_document_type | E1: llm_doctype_mismatch | F1: llm_support_label | G1: llm_commenter_type | H1: llm_project_state | I1: llm_project_region | J1: llm_feedback_theme_primary | K1: llm_feedback_theme_tags
A2: 5699 | B2: gemini-3.1-pro-preview | C2: substantive_comment | D2: substantive_comment | E2: 0 | F2: oppose | G2: nonprofit | H2: NM | I2: southwest | J2: economics_jobs | K2: economics_jobs|public_process
A3: 4699 | B3: gemini-3.1-pro-preview | C3: agency_submission | D3: procedural_filing | E3: 1 | F3: Neutral | G3: government | H3: WI | I3: midwest | J3: public_process | K3: public_process
A4: 9753 | B4: gemini-3.1-pro-preview | C4: agency_submission | D4: agency_submission | E4: 0 | F4: Support with Changes | G4: government | H4: WY | I4: northwest | J4: safety_risk | K4: water_impacts|wildlife_ecosystem|safety_risk
A5: 3658 | B5: gemini-3.1-pro-preview | C5: substantive_comment | D5: substantive_comment | E5: 0 | F5: oppose | G5: resident | H5: PA | I5: northeast | J5: water_impacts | K5: water_impacts|wildlife_ecosystem|public_process
A6: 7316 | B6: gemini-3.1-pro-preview | C6: substantive_comment | D6: substantive_comment | E6: 0 | F6: oppose | G6: resident | I6: northeast | J6: public_process | K6: public_process
A7: 3504 | B7: gemini-3.1-pro-preview | C7: substantive_comment | D7: substantive_comment | E7: 0 | F7: support | G7: nonprofit | I7: northeast | J7: economics_jobs | K7: economics_jobs|climate_energy
A8: 2910 | B8: gemini-3.1-pro-preview | C8: substantive_comment | D8: substantive_comment | E8: 0 | F8: oppose | G8: nonprofit | I8: northeast | J8: public_process | K8: public_process|climate_energy
A9: 3227 | B9: gemini-3.1-pro-preview | C9: substantive_comment | D9: substantive_comment | E9: 0 | F9: Support with Changes | G9: resident | I9: unknown | J9: wildlife_ecosystem | K9: wildlife_ecosystem
A10: 5810 | B10: gemini-3.1-pro-preview | C10: substantive_comment | D10: substantive_comment | E10: 0 | F10: Support with Changes | G10: nonprofit | H10: Minnesota | I10: midwest | J10: cultural_historic | K10: cultural_historic|public_process
A11: 6468 | B11: gemini-3.1-pro-preview | C11: agency_submission | D11: procedural_filing | E11: 1 | F11: Neutral | G11: government | H11: TN | I11: southeast | J11: public_process | K11: cultural_historic|public_process
A12: 10180 | B12: gemini-3.1-pro-preview | C12: substantive_comment | D12: substantive_comment | E12: 0 | F12: oppose | G12: resident | I12: midwest | J12: wildlife_ecosystem | K12: wildlife_ecosystem|climate_energy
A13: 7264 | B13: gemini-3.1-pro-preview | C13: substantive_comment | D13: substantive_comment | E13: 0 | F13: Support with Changes | G13: landowner | H13: KY | I13: southeast | J13: cultural_historic | K13: cultural_historic|water_impacts
A14: 9707 | B14: gemini-3.1-pro-preview | C14: substantive_comment | D14: substantive_comment | E14: 0 | F14: support | G14: government | H14: KY | I14: southeast | J14: climate_energy | K14: economics_jobs|climate_energy
A15: 4866 | B15: gemini-3.1-pro-preview | C15: substantive_comment | D15: substantive_comment | E15: 0 | F15: Support with Changes | G15: government | H15: CA | I15: southwest | J15: economics_jobs | K15: economics_jobs|other
A16: 3280 | B16: gemini-3.1-pro-preview | C16: substantive_comment | D16: substantive_comment | E16: 0 | F16: support | G16: resident | H16: LA | I16: south_central | J16: economics_jobs | K16: economics_jobs
A17: 2307 | B17: gemini-3.1-pro-preview | C17: substantive_comment | D17: substantive_comment | E17: 0 | F17: Support with Changes | G17: nonprofit | H17: CA | I17: southwest | J17: wildlife_ecosystem | K17: water_impacts|wildlife_ecosystem|public_process|recreation_tourism
A18: 5174 | B18: gemini-3.1-pro-preview | C18: substantive_comment | D18: substantive_comment | E18: 0 | F18: oppose | G18: resident | I18: northeast | J18: wildlife_ecosystem | K18: wildlife_ecosystem|water_impacts
A19: 5807 | B19: gemini-3.1-pro-preview | C19: substantive_comment | D19: substantive_comment | E19: 0 | F19: Support with Changes | G19: resident | I19: northeast | J19: recreation_tourism | K19: recreation_tourism
A20: 5844 | B20: gemini-3.1-pro-preview | C20: substantive_comment | D20: procedural_filing | E20: 1 | F20: Neutral | G20: government | I20: northeast | J20: public_process | K20: public_process
A21: 2969 | B21: gemini-3.1-pro-preview | C21: substantive_comment | D21: substantive_comment | E21: 0 | F21: support | G21: business | I21: midwest | J21: public_process | K21: public_process
A22: 8401 | B22: gemini-3.1-pro-preview | C22: substantive_comment | D22: substantive_comment | E22: 0 | F22: support | G22: resident | H22: ME | I22: northeast | J22: wildlife_ecosystem | K22: wildlife_ecosystem|water_impacts
A23: 3747 | B23: gemini-3.1-pro-preview | C23: agency_submission | D23: agency_submission | E23: 0 | F23: Neutral | G23: government | H23: TX | I23: south_central | J23: wildlife_ecosystem | K23: wildlife_ecosystem|water_impacts|public_process
A24: 761 | B24: gemini-3.1-pro-preview | C24: substantive_comment | D24: substantive_comment | E24: 0 | F24: support | G24: business | H24: FL | I24: southeast | J24: economics_jobs | K24: economics_jobs
A25: 5344 | B25: gemini-3.1-pro-preview | C25: substantive_comment | D25: substantive_comment | E25: 0 | F25: oppose | G25: resident | H25: NY | I25: northeast | J25: public_process | K25: water_impacts|public_process
A26: 729 | B26: gemini-3.1-pro-preview | C26: substantive_comment | D26: procedural_filing | E26: 1 | F26: Neutral | G26: unknown | I26: unknown | J26: climate_energy | K26: climate_energy|economics_jobs
A27: 2782 | B27: gemini-3.1-pro-preview | C27: substantive_comment | D27: procedural_filing | E27: 1 | F27: Neutral | G27: business | I27: midwest | J27: public_process | K27: public_process
A28: 951 | B28: gemini-3.1-pro-preview | C28: substantive_comment | D28: substantive_comment | E28: 0 | F28: oppose | G28: landowner | H28: KY | I28: southeast | J28: safety_risk | K28: safety_risk|public_process|property_rights
A29: 9370 | B29: gemini-3.1-pro-preview | C29: substantive_comment | D29: substantive_comment | E29: 0 | F29: oppose | G29: resident | I29: northwest | J29: other | K29: other
A30: 2937 | B30: gemini-3.1-pro-preview | C30: substantive_comment | D30: substantive_comment | E30: 0 | F30: Support with Changes | G30: government | I30: south_central | J30: public_process | K30: public_process
A31: 4745 | B31: gemini-3.1-pro-preview | C31: substantive_comment | D31: substantive_comment | E31: 0 | F31: support | G31: government | H31: KY | I31: midwest | J31: climate_energy | K31: climate_energy|economics_jobs
A32: 241 | B32: gemini-3.1-pro-preview | C32: agency_submission | D32: agency_submission | E32: 0 | F32: Support with Changes | G32: government | H32: WY | I32: midwest | J32: wildlife_ecosystem | K32: water_impacts|wildlife_ecosystem
A33: 5265 | B33: gemini-3.1-pro-preview | C33: agency_submission | D33: agency_submission | E33: 0 | F33: Support with Changes | G33: government | H33: PA | I33: northeast | J33: wildlife_ecosystem | K33: wildlife_ecosystem|water_impacts
A34: 7256 | B34: gemini-3.1-pro-preview | C34: agency_submission | D34: agency_submission | E34: 0 | F34: support | G34: government | H34: VA | I34: southeast | J34: wildlife_ecosystem | K34: wildlife_ecosystem
A35: 6563 | B35: gemini-3.1-pro-preview | C35: substantive_comment | D35: substantive_comment | E35: 0 | F35: support | G35: nonprofit | I35: other | J35: public_process | K35: climate_energy|public_process
A36: 779 | B36: gemini-3.1-pro-preview | C36: substantive_comment | D36: substantive_comment | E36: 0 | F36: oppose | G36: resident | I36: northeast | J36: water_impacts | K36: water_impacts|property_rights
A37: 10179 | B37: gemini-3.1-pro-preview | C37: substantive_comment | D37: substantive_comment | E37: 0 | F37: oppose | G37: resident | I37: south_central | J37: recreation_tourism | K37: wildlife_ecosystem|recreation_tourism
A38: 6588 | B38: gemini-3.1-pro-preview | C38: substantive_comment | D38: substantive_comment | E38: 0 | F38: oppose | G38: business | I38: midwest | J38: economics_jobs | K38: economics_jobs|other
A39: 7805 | B39: gemini-3.1-pro-preview | C39: substantive_comment | D39: substantive_comment | E39: 0 | F39: oppose | G39: government | H39: NV | I39: southwest | J39: public_process | K39: public_process|water_impacts|economics_jobs
A40: 2920 | B40: gemini-3.1-pro-preview | C40: substantive_comment | D40: substantive_comment | E40: 0 | F40: support | G40: government | H40: WA | I40: northwest | J40: public_process | K40: public_process|climate_energy
...

Sheet gpt-5.4
A1: pdf_id | B1: model | C1: llm_document_type | D1: llm_model_document_type | E1: llm_doctype_mismatch | F1: llm_support_label | G1: llm_commenter_type | H1: llm_project_state | I1: llm_project_region | J1: llm_feedback_theme_primary | K1: llm_feedback_theme_tags
A2: 5699 | B2: gpt-5.4 | C2: substantive_comment | D2: substantive_comment | E2: 0 | F2: oppose | G2: nonprofit | H2: NM | I2: southwest | J2: economics_jobs | K2: other|climate_energy|other|economics_jobs
A3: 4699 | B3: gpt-5.4 | C3: agency_submission | D3: procedural_filing | E3: 1 | F3: Neutral | G3: government | H3: WI | I3: midwest | J3: public_process | K3: other
A4: 9753 | B4: gpt-5.4 | C4: agency_submission | D4: agency_submission | E4: 0 | F4: Support with Changes | G4: government | H4: WY | I4: unknown | J4: water_impacts | K4: other|wildlife_ecosystem|public_process|recreation_tourism|cultural_historic|climate_energy
A5: 3658 | B5: gpt-5.4 | C5: substantive_comment | D5: substantive_comment | E5: 0 | F5: Neutral | G5: resident | I5: northeast | J5: water_impacts | K5: wildlife_ecosystem|public_process|property_rights
A6: 7316 | B6: gpt-5.4 | C6: substantive_comment | D6: substantive_comment | E6: 0 | F6: oppose | G6: unknown | I6: unknown | J6: public_process | K6: public_process
A7: 3504 | B7: gpt-5.4 | C7: substantive_comment | D7: procedural_filing | E7: 1 | F7: Neutral | G7: nonprofit | I7: northeast | J7: public_process | K7: economics_jobs|grid_reliability
A8: 2910 | B8: gpt-5.4 | C8: substantive_comment | D8: procedural_filing | E8: 1 | F8: Neutral | G8: business | I8: unknown | J8: public_process | K8: grid_reliability|public_process
A9: 3227 | B9: gpt-5.4 | C9: substantive_comment | D9: substantive_comment | E9: 0 | F9: Support with Changes | G9: resident | I9: unknown | J9: wildlife_ecosystem | K9: wildlife_ecosystem|public_process
A10: 5810 | B10: gpt-5.4 | C10: substantive_comment | D10: substantive_comment | E10: 0 | F10: Support with Changes | G10: nonprofit | H10: Minnesota | I10: midwest | J10: cultural_historic | K10: public_process|water_impacts
A11: 6468 | B11: gpt-5.4 | C11: agency_submission | D11: procedural_filing | E11: 1 | F11: Neutral | G11: government | H11: Tennessee | I11: southeast | J11: public_process | K11: cultural_historic|public_process
A12: 10180 | B12: gpt-5.4 | C12: substantive_comment | D12: substantive_comment | E12: 0 | F12: oppose | G12: resident | I12: midwest | J12: climate_energy | K12: other|wildlife_ecosystem|climate_energy
A13: 7264 | B13: gpt-5.4 | C13: substantive_comment | D13: substantive_comment | E13: 0 | F13: Support with Changes | G13: unknown | H13: KY | I13: south_central | J13: cultural_historic | K13: other|property_rights|public_process
A14: 9707 | B14: gpt-5.4 | C14: substantive_comment | D14: substantive_comment | E14: 0 | F14: support | G14: government | H14: KY | I14: south_central | J14: economics_jobs | K14: grid_reliability|climate_energy|economics_jobs
A15: 4866 | B15: gpt-5.4 | C15: substantive_comment | D15: procedural_filing | E15: 1 | F15: Neutral | G15: government | H15: California | I15: unknown | J15: public_process | K15: economics_jobs|public_process
A16: 3280 | B16: gpt-5.4 | C16: substantive_comment | D16: substantive_comment | E16: 0 | F16: support | G16: resident | H16: LA | I16: south_central | J16: economics_jobs | K16: economics_jobs|property_rights|other
A17: 2307 | B17: gpt-5.4 | C17: substantive_comment | D17: substantive_comment | E17: 0 | F17: Support with Changes | G17: nonprofit | H17: CA | I17: unknown | J17: water_impacts | K17: wildlife_ecosystem|public_process|recreation_tourism
A18: 5174 | B18: gpt-5.4 | C18: substantive_comment | D18: substantive_comment | E18: 0 | F18: oppose | G18: resident | I18: northeast | J18: wildlife_ecosystem | K18: other|wildlife_ecosystem|climate_energy
A19: 5807 | B19: gpt-5.4 | C19: substantive_comment | D19: substantive_comment | E19: 0 | F19: Support with Changes | G19: unknown | H19: PA | I19: northeast | J19: recreation_tourism | K19: public_process
A20: 5844 | B20: gpt-5.4 | C20: substantive_comment | D20: procedural_filing | E20: 1 | F20: Neutral | G20: business | I20: northeast | J20: public_process | K20: economics_jobs
A21: 2969 | B21: gpt-5.4 | C21: substantive_comment | D21: procedural_filing | E21: 1 | F21: Neutral | G21: business | I21: unknown | J21: public_process | K21: public_process
A22: 8401 | B22: gpt-5.4 | C22: substantive_comment | D22: substantive_comment | E22: 0 | F22: support | G22: unknown | H22: ME | I22: northeast | J22: water_impacts | K22: other|economics_jobs
A23: 3747 | B23: gpt-5.4 | C23: agency_submission | D23: agency_submission | E23: 0 | F23: Support with Changes | G23: government | H23: Texas | I23: south_central | J23: wildlife_ecosystem | K23: other|other|other
A24: 761 | B24: gpt-5.4 | C24: substantive_comment | D24: procedural_filing | E24: 1 | F24: Neutral | G24: business | H24: FL | I24: southeast | J24: public_process | K24: public_process
A25: 5344 | B25: gpt-5.4 | C25: substantive_comment | D25: substantive_comment | E25: 0 | F25: oppose | G25: resident | H25: NY | I25: northeast | J25: water_impacts | K25: other|water_impacts|climate_energy
A26: 729 | B26: gpt-5.4 | C26: substantive_comment | D26: procedural_filing | E26: 1 | F26: Neutral | G26: business | I26: unknown | J26: grid_reliability | K26: economics_jobs|climate_energy|public_process
A27: 2782 | B27: gpt-5.4 | C27: substantive_comment | D27: procedural_filing | E27: 1 | F27: Neutral | G27: business | I27: midwest | J27: public_process | K27: grid_reliability|economics_jobs
A28: 951 | B28: gpt-5.4 | C28: substantive_comment | D28: substantive_comment | E28: 0 | F28: oppose | G28: landowner | H28: KY | I28: south_central | J28: property_rights | K28: other|safety_risk|other|wildlife_ecosystem|cultural_historic|climate_energy|economics_jobs
A29: 9370 | B29: gpt-5.4 | C29: substantive_comment | D29: substantive_comment | E29: 0 | F29: oppose | G29: resident | I29: unknown | J29: water_impacts | K29: water_impacts|public_process
A30: 2937 | B30: gpt-5.4 | C30: substantive_comment | D30: procedural_filing | E30: 1 | F30: Neutral | G30: government | H30: OK | I30: south_central | J30: public_process | K30: economics_jobs|other
A31: 4745 | B31: gpt-5.4 | C31: substantive_comment | D31: substantive_comment | E31: 0 | F31: support | G31: government | H31: KY | I31: south_central | J31: grid_reliability | K31: economics_jobs|climate_energy
A32: 241 | B32: gpt-5.4 | C32: agency_submission | D32: agency_submission | E32: 0 | F32: Support with Changes | G32: government | H32: Wyoming | I32: northwest | J32: wildlife_ecosystem | K32: other|wildlife_ecosystem|other
A33: 5265 | B33: gpt-5.4 | C33: agency_submission | D33: agency_submission | E33: 0 | F33: Support with Changes | G33: government | H33: PA | I33: northeast | J33: wildlife_ecosystem | K33: other|wildlife_ecosystem
A34: 7256 | B34: gpt-5.4 | C34: agency_submission | D34: agency_submission | E34: 0 | F34: support | G34: government | H34: VA | I34: southeast | J34: wildlife_ecosystem | K34: other|wildlife_ecosystem
A35: 6563 | B35: gpt-5.4 | C35: substantive_comment | D35: substantive_comment | E35: 0 | F35: support | G35: business | I35: unknown | J35: grid_reliability | K35: grid_reliability|other|economics_jobs
A36: 779 | B36: gpt-5.4 | C36: substantive_comment | D36: procedural_filing | E36: 1 | F36: Neutral | G36: unknown | I36: other | J36: public_process | K36: other|property_rights
A37: 10179 | B37: gpt-5.4 | C37: substantive_comment | D37: substantive_comment | E37: 0 | F37: oppose | G37: resident | I37: other | J37: water_impacts | K37: recreation_tourism|water_impacts
A38: 6588 | B38: gpt-5.4 | C38: substantive_comment | D38: procedural_filing | E38: 1 | F38: Neutral | G38: business | I38: midwest | J38: public_process | K38: economics_jobs|public_process
A39: 7805 | B39: gpt-5.4 | C39: substantive_comment | D39: substantive_comment | E39: 0 | F39: oppose | G39: government | H39: Nevada | I39: unknown | J39: public_process | K39: other|public_process|property_rights
A40: 2920 | B40: gpt-5.4 | C40: substantive_comment | D40: procedural_filing | E40: 1 | F40: Neutral | G40: government | H40: WA | I40: northwest | J40: public_process | K40: grid_reliability|economics_jobs
...

Sheet claude-opus-4-6
A1: pdf_id | B1: model | C1: llm_document_type | D1: llm_model_document_type | E1: llm_doctype_mismatch | F1: llm_support_label | G1: llm_commenter_type | H1: llm_project_state | I1: llm_project_region | J1: llm_feedback_theme_primary | K1: llm_feedback_theme_tags
A2: 5699 | B2: claude-opus-4-6 | C2: substantive_comment | D2: substantive_comment | E2: 0 | F2: oppose | G2: nonprofit | H2: NM | I2: southwest | J2: economics_jobs | K2: economics_jobs|public_process|grid_reliability|other
A3: 4699 | B3: claude-opus-4-6 | C3: agency_submission | D3: agency_submission | E3: 0 | F3: support | G3: government | H3: WI | I3: midwest | J3: water_impacts | K3: water_impacts|public_process
A4: 9753 | B4: claude-opus-4-6 | C4: agency_submission | D4: agency_submission | E4: 0 | F4: Support with Changes | G4: government | H4: WY | I4: northwest | J4: water_impacts | K4: water_impacts|wildlife_ecosystem|safety_risk|recreation_tourism|cultural_historic|public_process
A5: 3658 | B5: claude-opus-4-6 | C5: substantive_comment | D5: substantive_comment | E5: 0 | F5: oppose | G5: resident | H5: PA | I5: northeast | J5: water_impacts | K5: water_impacts|wildlife_ecosystem|public_process|property_rights|safety_risk
A6: 7316 | B6: claude-opus-4-6 | C6: substantive_comment | D6: substantive_comment | E6: 0 | F6: oppose | G6: resident | I6: unknown | J6: public_process | K6: public_process
A7: 3504 | B7: claude-opus-4-6 | C7: substantive_comment | D7: substantive_comment | E7: 0 | F7: support | G7: nonprofit | I7: northeast | J7: economics_jobs | K7: economics_jobs|climate_energy|grid_reliability
A8: 2910 | B8: claude-opus-4-6 | C8: substantive_comment | D8: agency_submission | E8: 1 | F8: oppose | G8: government | I8: unknown | J8: grid_reliability | K8: grid_reliability|public_process|other
A9: 3227 | B9: claude-opus-4-6 | C9: substantive_comment | D9: substantive_comment | E9: 0 | F9: Support with Changes | G9: resident | I9: unknown | J9: wildlife_ecosystem | K9: wildlife_ecosystem
A10: 5810 | B10: claude-opus-4-6 | C10: substantive_comment | D10: substantive_comment | E10: 0 | F10: Support with Changes | G10: nonprofit | H10: Minnesota | I10: midwest | J10: cultural_historic | K10: cultural_historic|public_process|other
A11: 6468 | B11: claude-opus-4-6 | C11: agency_submission | D11: agency_submission | E11: 0 | F11: support | G11: government | H11: TN | I11: southeast | J11: cultural_historic | K11: cultural_historic|public_process
A12: 10180 | B12: claude-opus-4-6 | C12: substantive_comment | D12: substantive_comment | E12: 0 | F12: oppose | G12: resident | I12: unknown | J12: wildlife_ecosystem | K12: wildlife_ecosystem|climate_energy|other
A13: 7264 | B13: claude-opus-4-6 | C13: substantive_comment | D13: substantive_comment | E13: 0 | F13: Support with Changes | G13: resident | H13: KY | I13: southeast | J13: cultural_historic | K13: cultural_historic|water_impacts|wildlife_ecosystem|property_rights|public_process
A14: 9707 | B14: claude-opus-4-6 | C14: substantive_comment | D14: substantive_comment | E14: 0 | F14: support | G14: government | H14: KY | I14: midwest | J14: climate_energy | K14: climate_energy|economics_jobs|grid_reliability
A15: 4866 | B15: claude-opus-4-6 | C15: substantive_comment | D15: substantive_comment | E15: 0 | F15: oppose | G15: government | H15: California | I15: southwest | J15: economics_jobs | K15: economics_jobs|public_process|grid_reliability
A16: 3280 | B16: claude-opus-4-6 | C16: substantive_comment | D16: substantive_comment | E16: 0 | F16: support | G16: resident | H16: LA | I16: south_central | J16: economics_jobs | K16: economics_jobs|public_process|safety_risk|other
A17: 2307 | B17: claude-opus-4-6 | C17: substantive_comment | D17: substantive_comment | E17: 0 | F17: Support with Changes | G17: nonprofit | H17: CA | I17: southwest | J17: wildlife_ecosystem | K17: wildlife_ecosystem|water_impacts|public_process|recreation_tourism
A18: 5174 | B18: claude-opus-4-6 | C18: substantive_comment | D18: substantive_comment | E18: 0 | F18: oppose | G18: resident | I18: unknown | J18: wildlife_ecosystem | K18: wildlife_ecosystem|water_impacts|climate_energy
A19: 5807 | B19: claude-opus-4-6 | C19: substantive_comment | D19: substantive_comment | E19: 0 | F19: Support with Changes | G19: resident | I19: northeast | J19: recreation_tourism | K19: recreation_tourism|public_process
A20: 5844 | B20: claude-opus-4-6 | C20: substantive_comment | D20: procedural_filing | E20: 1 | F20: Neutral | G20: government | I20: northeast | J20: grid_reliability | K20: grid_reliability|economics_jobs
A21: 2969 | B21: claude-opus-4-6 | C21: substantive_comment | D21: substantive_comment | E21: 0 | F21: support | G21: business | I21: unknown | J21: public_process | K21: public_process|other
A22: 8401 | B22: claude-opus-4-6 | C22: substantive_comment | D22: substantive_comment | E22: 0 | F22: support | G22: resident | H22: ME | I22: northeast | J22: wildlife_ecosystem | K22: wildlife_ecosystem|economics_jobs|water_impacts
A23: 3747 | B23: claude-opus-4-6 | C23: agency_submission | D23: agency_submission | E23: 0 | F23: Support with Changes | G23: government | H23: TX | I23: south_central | J23: wildlife_ecosystem | K23: wildlife_ecosystem|water_impacts|climate_energy|safety_risk
A24: 761 | B24: claude-opus-4-6 | C24: substantive_comment | D24: procedural_filing | E24: 1 | F24: Neutral | G24: business | H24: FL | I24: southeast | J24: grid_reliability | K24: grid_reliability|economics_jobs
A25: 5344 | B25: claude-opus-4-6 | C25: substantive_comment | D25: substantive_comment | E25: 0 | F25: oppose | G25: resident | H25: NY | I25: northeast | J25: public_process | K25: public_process|water_impacts|wildlife_ecosystem|climate_energy
A26: 729 | B26: claude-opus-4-6 | C26: substantive_comment | D26: procedural_filing | E26: 1 | F26: Neutral | G26: business | I26: unknown | J26: grid_reliability | K26: grid_reliability|climate_energy|economics_jobs|other
A27: 2782 | B27: claude-opus-4-6 | C27: substantive_comment | D27: procedural_filing | E27: 1 | F27: Neutral | G27: business | I27: midwest | J27: grid_reliability | K27: grid_reliability|economics_jobs|public_process
A28: 951 | B28: claude-opus-4-6 | C28: substantive_comment | D28: substantive_comment | E28: 0 | F28: oppose | G28: landowner | H28: KY | I28: midwest | J28: safety_risk | K28: safety_risk|public_process|wildlife_ecosystem|climate_energy|property_rights|cultural_historic|water_impacts
A29: 9370 | B29: claude-opus-4-6 | C29: substantive_comment | D29: substantive_comment | E29: 0 | F29: oppose | G29: resident | I29: unknown | J29: public_process | K29: public_process|other
A30: 2937 | B30: claude-opus-4-6 | C30: substantive_comment | D30: substantive_comment | E30: 0 | F30: support | G30: government | H30: OK | I30: south_central | J30: public_process | K30: public_process|economics_jobs|grid_reliability|other
A31: 4745 | B31: claude-opus-4-6 | C31: substantive_comment | D31: substantive_comment | E31: 0 | F31: support | G31: government | H31: KY | I31: midwest | J31: grid_reliability | K31: grid_reliability|economics_jobs|climate_energy
A32: 241 | B32: claude-opus-4-6 | C32: agency_submission | D32: agency_submission | E32: 0 | F32: Support with Changes | G32: government | H32: WY | I32: northwest | J32: wildlife_ecosystem | K32: wildlife_ecosystem|water_impacts|other
A33: 5265 | B33: claude-opus-4-6 | C33: agency_submission | D33: agency_submission | E33: 0 | F33: Support with Changes | G33: government | H33: PA | I33: northeast | J33: wildlife_ecosystem | K33: wildlife_ecosystem|water_impacts|public_process
A34: 7256 | B34: claude-opus-4-6 | C34: agency_submission | D34: agency_submission | E34: 0 | F34: support | G34: government | H34: VA | I34: southeast | J34: wildlife_ecosystem | K34: wildlife_ecosystem|water_impacts
A35: 6563 | B35: claude-opus-4-6 | C35: substantive_comment | D35: substantive_comment | E35: 0 | F35: support | G35: nonprofit | I35: unknown | J35: grid_reliability | K35: grid_reliability|climate_energy|other
A36: 779 | B36: claude-opus-4-6 | C36: substantive_comment | D36: substantive_comment | E36: 0 | F36: oppose | G36: nonprofit | H36: Maryland | I36: southeast | J36: water_impacts | K36: water_impacts|property_rights|wildlife_ecosystem
A37: 10179 | B37: claude-opus-4-6 | C37: substantive_comment | D37: substantive_comment | E37: 0 | F37: oppose | G37: resident | H37: WY | I37: northwest | J37: water_impacts | K37: water_impacts|wildlife_ecosystem|recreation_tourism
A38: 6588 | B38: claude-opus-4-6 | C38: substantive_comment | D38: procedural_filing | E38: 1 | F38: Neutral | G38: business | I38: midwest | J38: economics_jobs | K38: economics_jobs|grid_reliability|other
A39: 7805 | B39: claude-opus-4-6 | C39: substantive_comment | D39: substantive_comment | E39: 0 | F39: oppose | G39: government | H39: NV | I39: southwest | J39: public_process | K39: public_process|water_impacts|economics_jobs
A40: 2920 | B40: claude-opus-4-6 | C40: substantive_comment | D40: substantive_comment | E40: 0 | F40: support | G40: government | H40: WA | I40: northwest | J40: public_process | K40: public_process|grid_reliability|economics_jobs|climate_energy
...

Sheet Sheet1

Sheet Hand Coded
A1: pdf_id | B1: llm_support_label | C1: Feedback Theme | D1: Project Type | E1: Commenter Type | F1: Project State | G1: Project Region
A2: 138 | B2: Support with Changes | C2: public_process | D2: market_rate | E2: business | F2: Unknown | G2: Unknown
A3: 241 | B3: Support with Changes | C3: wildlife_ecosystem | D3: hydropower | E3: government | F3: WY | G3: northwest
A4: 259 | B4: Neutral | C4: public_process | D4: market_rate | E4: business | F4: Unknown | G4: Unknown
A5: 264 | B5: Oppose | C5: wildlife_ecosystem | D5: hydropower | E5: government | F5: MI | G5: midwest
A6: 273 | B6: Neutral | C6: public_process | D6: hydropower | E6: government | F6: Unknown | G6: Unknown
A7: 383 | B7: Support with Changes | C7: wildlife_ecosystem | D7: hydropower | E7: government | F7: ME | G7: northeast
A8: 416 | B8: Support with Changes | C8: water_impacts | D8: hydropower | E8: government | F8: OR | G8: northwest
A9: 474 | B9: Neutral | C9: public_process | D9: hydropower | E9: government | F9: CA | G9: southwest
A10: 516 | B10: Support with Changes | C10: wildlife_ecosystem | D10: hydropower | E10: government | F10: CT | G10: northeast
A11: 729 | B11: Neutral | C11: other | D11: grid_reliability | E11: business | F11: Unknown | G11: Unknown
A12: 761 | B12: Support | C12: economics_jobs | D12: natural_gas_pipeline | E12: business | F12: FL | G12: southeast
A13: 779 | B13: Oppose | C13: water_impacts | D13: natural_gas_pipeline | E13: nonprofit | F13: MD | G13: southeast
... A218: 6550 | B218: Oppose | C218: property_rights | D218: natural_gas_pipeline | E218: resident | F218: NY | G218: Northeast
A219: 6552 | B219: Neutral | C219: grid_reliability | D219: natural_gas_pipeline | E219: organization
A220: 6563 | B220: Support | C220: public_process | D220: natural_gas_pipeline | E220: business | F220: multiple states
A221: 6588 | B221: Neutral | C221: property_rights | D221: natural_gas_pipeline | E221: resident | F221: NY | G221: Northeast
A222: 6601 | B222: Neutral | C222: grid_reliability | D222: electric_transmission | E222: organization | F222: multiple states
A223: 6619 | B223: Support | C223: public_process | D223: natural_gas_pipeline | E223: organziation | F223: multiple states
A224: 6629 | B224: Support | C224: public_process | D224: electric_transmission | E224: organization | F224: multiple states
A225: 6737 | B225: Oppose | C225: public_process | D225: natural_gas_pipeline | E225: resident | F225: NY | G225: Northeast
A226: 6929 | B226: Oppose | C226: hydropower | D226: natural_gas_pipeline | E226: government | F226: MI | G226: Midwest
A227: 6988 | B227: Support | C227: wildlife_ecosystem | D227: hydropower | E227: organization | F227: VA | G227: Southeast
A228: 7256 | B228: Support | C228: wildlife_ecosystem | D228: hydropower | E228: organization | F228: VA | G228: Southeast
A229: 7264 | B229: Oppose | C229: history | D229: natural_gas_pipeline | E229: resident | F229: KY | G229: Southeast
A230: 7289 | B230: Oppose | C230: wildlife_ecosystem | D230: hydropower | E230: government | F230: VA | G230: Southeast
A231: 7316 | B231: Oppose | C231: public_process | D231: natural_gas_pipeline | E231: resident | F231: NY | G231: Northeast
A232: 6955 | B232: Oppose | C232: public_process | D232: natural_gas_pipeline | E232: organization | F232: NY | G232: Northeast
A233: 4746 | B233: Support | C233: economics_jobs | D233: natural_gas_pipeline | E233: organization | F233: KY | G233: Southeast
A234: 1485 | B234: Oppose | C234: wildlife_ecosystem | D234: natural_gas_pipeline | E234: organization | G234: Midwest
A235: 9768 | B235: Oppose | C235: wildlife_ecosystem | D235: hydropower | E235: resident | F235: WY | G235: West

Sheet Accuracy Table
A1: gemini-3.1-pro-preview
A2: Manually Identified Stance | B2: Number Correct | C2: Total Number of Manually Identified Entries | D2: Recall (%)
A3: Support | B3: {=SUMPRODUCT(('Hand Coded'!B$1:B$10000="Support")*(IFERROR(INDEX('gemini-3.1-pro-preview'!$F:$F,MATCH('Hand Coded'!A$1:A$10000,'gemini-3.1-pro-preview'!$A:$A,0)),"")="support"))} -> 34 | C3: =COUNTIF('Hand Coded'!B:B,"Support") -> 47 | D3: =IF(C3=0,0,B3/C3) -> 0.72340426
A4: Support with Changes | B4: {=SUMPRODUCT(('Hand Coded'!B$1:B$10000="Support with Changes")*(IFERROR(INDEX('gemini-3.1-pro-preview'!$F:$F,MATCH('Hand Coded'!A$1:A$10000,'gemini-3.1-pro-preview'!$A:$A,0)),"")="Support with Changes"))} -> 33 | C4: =COUNTIF('Hand Coded'!B:B,"Support with Changes") -> 39 | D4: =IF(C4=0,0,B4/C4) -> 0.84615385
A5: Oppose | B5: {=SUMPRODUCT(('Hand Coded'!B$1:B$10000="Oppose")*(IFERROR(INDEX('gemini-3.1-pro-preview'!$F:$F,MATCH('Hand Coded'!A$1:A$10000,'gemini-3.1-pro-preview'!$A:$A,0)),"")="oppose"))} -> 85 | C5: =COUNTIF('Hand Coded'!B:B,"Oppose") -> 101 | D5: =IF(C5=0,0,B5/C5) -> 0.84158416
A6: Neutral | B6: {=SUMPRODUCT(('Hand Coded'!B$1:B$10000="Neutral")*(IFERROR(INDEX('gemini-3.1-pro-preview'!$F:$F,MATCH('Hand Coded'!A$1:A$10000,'gemini-3.1-pro-preview'!$A:$A,0)),"")="Neutral"))} -> 35 | C6: =COUNTIF('Hand Coded'!B:B,"Neutral") -> 47 | D6: =IF(C6=0,0,B6/C6) -> 0.74468085
A7: Total | B7: =SUM(B3:B6) -> 187 | C7: =SUM(C3:C6) -> 234 | D7: =IF(C7=0,0,B7/C7) -> 0.7991453
A9: gpt-5.4
A10: Manually Identified Stance | B10: Number Correct | C10: Total Number of Manually Identified Entries | D10: Recall (%)
A11: Support | B11: {=SUMPRODUCT(('Hand Coded'!B$1:B$10000="Support")*(IFERROR(INDEX('gpt-5.4'!$F:$F,MATCH('Hand Coded'!A$1:A$10000,'gpt-5.4'!$A:$A,0)),"")="support"))} -> 29 | C11: =C3 -> 47 | D11: =IF(C11=0,0,B11/C11) -> 0.61702128
A12: Support with Changes | B12: {=SUMPRODUCT(('Hand Coded'!B$1:B$10000="Support with Changes")*(IFERROR(INDEX('gpt-5.4'!$F:$F,MATCH('Hand Coded'!A$1:A$10000,'gpt-5.4'!$A:$A,0)),"")="Support with Changes"))} -> 29 | C12: =C4 -> 39 | D12: =IF(C12=0,0,B12/C12) -> 0.74358974
A13: Oppose | B13: {=SUMPRODUCT(('Hand Coded'!B$1:B$10000="Oppose")*(IFERROR(INDEX('gpt-5.4'!$F:$F,MATCH('Hand Coded'!A$1:A$10000,'gpt-5.4'!$A:$A,0)),"")="oppose"))} -> 63 | C13: =C5 -> 101 | D13: =IF(C13=0,0,B13/C13) -> 0.62376238
A14: Neutral | B14: {=SUMPRODUCT(('Hand Coded'!B$1:B$10000="Neutral")*(IFERROR(INDEX('gpt-5.4'!$F:$F,MATCH('Hand Coded'!A$1:A$10000,'gpt-5.4'!$A:$A,0)),"")="Neutral"))} -> 39 | C14: =C6 -> 47 | D14: =IF(C14=0,0,B14/C14) -> 0.82978723
A15: Total | B15: =SUM(B11:B14) -> 160 | C15: =SUM(C11:C14) -> 234 | D15: =IF(C15=0,0,B15/C15) -> 0.68376068
A17: claude-opus-4-6
A18: Manually Identified Stance | B18: Number Correct | C18: Total Number of Manually Identified Entries | D18: Recall (%)
A19: Support | B19: {=SUMPRODUCT(('Hand Coded'!B$1:B$10000="Support")*(IFERROR(INDEX('claude-opus-4-6'!$F:$F,MATCH('Hand Coded'!A$1:A$10000,'claude-opus-4-6'!$A:$A,0)),"")="support"))} -> 38 | C19: =C3 -> 47 | D19: =IF(C19=0,0,B19/C19) -> 0.80851064
A20: Support with Changes | B20: {=SUMPRODUCT(('Hand Coded'!B$1:B$10000="Support with Changes")*(IFERROR(INDEX('claude-opus-4-6'!$F:$F,MATCH('Hand Coded'!A$1:A$10000,'claude-opus-4-6'!$A:$A,0)),"")="Support with Changes"))} -> 30 | C20: =C4 -> 39 | D20: =IF(C20=0,0,B20/C20) -> 0.76923077
A21: Oppose | B21: {=SUMPRODUCT(('Hand Coded'!B$1:B$10000="Oppose")*(IFERROR(INDEX('claude-opus-4-6'!$F:$F,MATCH('Hand Coded'!A$1:A$10000,'claude-opus-4-6'!$A:$A,0)),"")="oppose"))} -> 91 | C21: =C5 -> 101 | D21: =IF(C21=0,0,B21/C21) -> 0.9009901
A22: Neutral | B22: {=SUMPRODUCT(('Hand Coded'!B$1:B$10000="Neutral")*(IFERROR(INDEX('claude-opus-4-6'!$F:$F,MATCH('Hand Coded'!A$1:A$10000,'claude-opus-4-6'!$A:$A,0)),"")="Neutral"))} -> 28 | C22: =C6 -> 47 | D22: =IF(C22=0,0,B22/C22) -> 0.59574468
A23: Total | B23: =SUM(B19:B22) -> 187 | C23: =SUM(C19:C22) -> 234 | D23: =IF(C23=0,0,B23/C23) -> 0.7991453

Sheet Error tracing
A1: Error Tracing: Accuracy by Document Type Mismatch Status
A2: Comparing model accuracy when llm_document_type matches vs. mismatches llm_model_document_type
A4: NO MISMATCH (llm_doctype_mismatch = 0)
A6: gemini-3.1-pro-preview (No Mismatch: 189 entries)
A7: Manually Identified Stance | B7: Number Correct | C7: Total Number of Manually Identified Entries | D7: Recall (%)
A8: Support | B8: 26 | C8: 42 | D8: =B8/C8 -> 0.61904762
A9: Support with Changes | B9: 22 | C9: 28 | D9: =B9/C9 -> 0.78571429
A10: Oppose | B10: 73 | C10: 79 | D10: =B10/C10 -> 0.92405063
A11: Neutral | B11: 2 | C11: 29 | D11: =B11/C11 -> 0.068965517
A12: Total | B12: =SUM(B8:B11) -> 123 | C12: =SUM(C8:C11) -> 178 | D12: =B12/C12 -> 0.69101124
A14: gpt-5.4 (No Mismatch: 156 entries)
A15: Manually Identified Stance | B15: Number Correct | C15: Total Number of Manually Identified Entries | D15: Recall (%)
A16: Support | B16: 23 | C16: 34 | D16: =B16/C16 -> 0.67647059
A17: Support with Changes | B17: 22 | C17: 24 | D17: =B17/C17 -> 0.91666667
A18: Oppose | B18: 58 | C18: 67 | D18: =B18/C18 -> 0.86567164
A19: Neutral | B19: 3 | C19: 21 | D19: =B19/C19 -> 0.14285714
A20: Total | B20: =SUM(B16:B19) -> 106 | C20: =SUM(C16:C19) -> 146 | D20: =B20/C20 -> 0.7260274
A22: claude-opus-4-6 (No Mismatch: 200 entries)
A23: Manually Identified Stance | B23: Number Correct | C23: Total Number of Manually Identified Entries | D23: Recall (%)
A24: Support | B24: 32 | C24: 43 | D24: =B24/C24 -> 0.74418605
A25: Support with Changes | B25: 21 | C25: 30 | D25: =B25/C25 -> 0.7
A26: Oppose | B26: 80 | C26: 82 | D26: =B26/C26 -> 0.97560976
A27: Neutral | B27: 0 | C27: 34 | D27: =B27/C27 -> 0
A28: Total | B28: =SUM(B24:B27) -> 133 | C28: =SUM(C24:C27) -> 189 | D28: =B28/C28 -> 0.7037037
A31: MISMATCH (llm_doctype_mismatch = 1)
A33: gemini-3.1-pro-preview (Mismatch: 51 entries)
A34: Manually Identified Stance | B34: Number Correct | C34: Total Number of Manually Identified Entries | D34: Recall (%)
A35: Support | B35: 1 | C35: 9 | D35: =B35/C35 -> 0.11111111
A36: Support with Changes | B36: 2 | C36: 2 | D36: =B36/C36 -> 1
A37: Oppose | B37: 5 | C37: 11 | D37: =B37/C37 -> 0.45454545
A38: Neutral | B38: 28 | C38: 29 | D38: =B38/C38 -> 0.96551724
A39: Total | B39: =SUM(B35:B38) -> 36 | C39: =SUM(C35:C38) -> 51 | D39: =B39/C39 -> 0.70588235
A41: gpt-5.4 (Mismatch: 84 entries)
A42: Manually Identified Stance | B42: Number Correct | C42: Total Number of Manually Identified Entries | D42: Recall (%)
A43: Support | B43: 1 | C43: 17 | D43: =B43/C43 -> 0.058823529
A44: Support with Changes | B44: 0 | C44: 6 | D44: =B44/C44 -> 0
A45: Oppose | B45: 0 | C45: 23 | D45: =B45/C45 -> 0
A46: Neutral | B46: 36 | C46: 37 | D46: =B46/C46 -> 0.97297297
A47: Total | B47: =SUM(B43:B46) -> 37 | C47: =SUM(C43:C46) -> 83 | D47: =B47/C47 -> 0.44578313
A49: claude-opus-4-6 (Mismatch: 40 entries)
...
