Workbook

Sheet gemini-3.1-flash-lite-preview
A1: pdf_id | B1: model | C1: llm_document_type | D1: llm_model_document_type | E1: llm_doctype_mismatch | F1: llm_support_label | G1: llm_project_type | H1: llm_commenter_type | I1: llm_project_state | J1: llm_project_region | K1: llm_feedback_theme_primary | L1: llm_feedback_theme_tags
A2: 5699 | B2: gemini-3.1-flash-lite-preview | C2: substantive_comment | D2: substantive_comment | E2: 0 | F2: oppose | G2: market_rate | H2: nonprofit | I2: NM | J2: southwest | K2: public_process | L2: public_process|economics_jobs
A3: 4699 | B3: gemini-3.1-flash-lite-preview | C3: agency_submission | D3: procedural_filing | E3: 1 | F3: Neutral | G3: hydropower | H3: government | I3: WI | J3: midwest | K3: public_process | L3: Unknown
A4: 9753 | B4: gemini-3.1-flash-lite-preview | C4: agency_submission | D4: agency_submission | E4: 0 | F4: Support with Changes | G4: market_rate | H4: government | I4: WY | J4: northwest | K4: water_impacts | L4: water_impacts|wildlife_ecosystem|safety_risk
A5: 3658 | B5: gemini-3.1-flash-lite-preview | C5: substantive_comment | D5: substantive_comment | E5: 0 | F5: Support with Changes | G5: hydropower | H5: resident | I5: PA | J5: northeast | K5: water_impacts | L5: water_impacts|wildlife_ecosystem|public_process
A6: 7316 | B6: gemini-3.1-flash-lite-preview | C6: substantive_comment | D6: substantive_comment | E6: 0 | F6: oppose | G6: hydropower | H6: resident | I6: Unknown | J6: northeast | K6: public_process | L6: public_process
A7: 3504 | B7: gemini-3.1-flash-lite-preview | C7: substantive_comment | D7: substantive_comment | E7: 0 | F7: support | G7: hydropower | H7: nonprofit | I7: Unknown | J7: northeast | K7: economics_jobs | L7: economics_jobs|climate_energy
A8: 2910 | B8: gemini-3.1-flash-lite-preview | C8: substantive_comment | D8: substantive_comment | E8: 0 | F8: oppose | G8: hydropower | H8: nonprofit | I8: Unknown | J8: midwest | K8: public_process | L8: climate_energy|public_process
A9: 3227 | B9: gemini-3.1-flash-lite-preview | C9: substantive_comment | D9: substantive_comment | E9: 0 | F9: Support with Changes | G9: hydropower | H9: resident | I9: Unknown | J9: unknown | K9: wildlife_ecosystem | L9: wildlife_ecosystem
A10: 5810 | B10: gemini-3.1-flash-lite-preview | C10: substantive_comment | D10: substantive_comment | E10: 0 | F10: Support with Changes | G10: hydropower | H10: nonprofit | I10: MN | J10: midwest | K10: cultural_historic | L10: cultural_historic|public_process
A11: 6468 | B11: gemini-3.1-flash-lite-preview | C11: agency_submission | D11: procedural_filing | E11: 1 | F11: Neutral | G11: market_rate | H11: government | I11: TN | J11: southeast | K11: public_process | L11: cultural_historic
A12: 10180 | B12: gemini-3.1-flash-lite-preview | C12: substantive_comment | D12: substantive_comment | E12: 0 | F12: oppose | G12: market_rate | H12: resident | I12: Unknown | J12: midwest | K12: wildlife_ecosystem | L12: wildlife_ecosystem|climate_energy
A13: 7264 | B13: gemini-3.1-flash-lite-preview | C13: substantive_comment | D13: substantive_comment | E13: 0 | F13: Support with Changes | G13: natural_gas_pipeline | H13: landowner | I13: KY | J13: southeast | K13: cultural_historic | L13: cultural_historic|water_impacts|public_process
... A241: 2967 | B241: gemini-3.1-flash-lite-preview | C241: agency_submission | D241: agency_submission | E241: 0 | F241: Neutral | G241: natural_gas_pipeline | H241: government | I241: OK | J241: south_central | K241: public_process | L241: public_process|cultural_historic

Sheet gpt-5.4-mini
A1: pdf_id | B1: model | C1: llm_document_type | D1: llm_model_document_type | E1: llm_doctype_mismatch | F1: llm_support_label | G1: llm_project_type | H1: llm_commenter_type | I1: llm_project_state | J1: llm_project_region | K1: llm_feedback_theme_primary | L1: llm_feedback_theme_tags
A2: 5699 | B2: gpt-5.4-mini | C2: substantive_comment | D2: substantive_comment | E2: 0 | F2: oppose | G2: market_rate | H2: nonprofit | I2: NM | J2: southwest | K2: economics_jobs | L2: other|other
A3: 4699 | B3: gpt-5.4-mini | C3: agency_submission | D3: procedural_filing | E3: 1 | F3: Neutral | G3: hydropower | H3: government | I3: WI | J3: midwest | K3: public_process | L3: public_process
A4: 9753 | B4: gpt-5.4-mini | C4: agency_submission | D4: agency_submission | E4: 0 | F4: Support with Changes | G4: market_rate | H4: government | I4: WY | J4: northwest | K4: water_impacts | L4: wildlife_ecosystem|public_process|recreation_tourism|cultural_historic|safety_risk
A5: 3658 | B5: gpt-5.4-mini | C5: substantive_comment | D5: substantive_comment | E5: 0 | F5: Support with Changes | G5: hydropower | H5: resident | I5: PA | J5: northeast | K5: water_impacts | L5: wildlife_ecosystem|public_process|property_rights
A6: 7316 | B6: gpt-5.4-mini | C6: substantive_comment | D6: substantive_comment | E6: 0 | F6: oppose | G6: hydropower | H6: resident | I6: Unknown | J6: unknown | K6: public_process | L6: public_process
A7: 3504 | B7: gpt-5.4-mini | C7: substantive_comment | D7: substantive_comment | E7: 0 | F7: support | G7: hydropower | H7: nonprofit | I7: NY | J7: northeast | K7: economics_jobs | L7: climate_energy
A8: 2910 | B8: gpt-5.4-mini | C8: substantive_comment | D8: substantive_comment | E8: 0 | F8: oppose | G8: hydropower | H8: business | I8: Unknown | J8: midwest | K8: grid_reliability | L8: other|grid_reliability
A9: 3227 | B9: gpt-5.4-mini | C9: substantive_comment | D9: substantive_comment | E9: 0 | F9: Support with Changes | G9: hydropower | H9: resident | I9: Unknown | J9: unknown | K9: wildlife_ecosystem | L9: wildlife_ecosystem
A10: 5810 | B10: gpt-5.4-mini | C10: substantive_comment | D10: substantive_comment | E10: 0 | F10: Support with Changes | G10: hydropower | H10: nonprofit | I10: MN | J10: midwest | K10: cultural_historic | L10: public_process|cultural_historic|other
A11: 6468 | B11: gpt-5.4-mini | C11: agency_submission | D11: procedural_filing | E11: 1 | F11: Neutral | G11: electric_transmission | H11: government | I11: TN | J11: southeast | K11: public_process | L11: cultural_historic|public_process
A12: 10180 | B12: gpt-5.4-mini | C12: substantive_comment | D12: substantive_comment | E12: 0 | F12: oppose | G12: market_rate | H12: resident | I12: Unknown | J12: midwest | K12: climate_energy | L12: other|wildlife_ecosystem|climate_energy
A13: 7264 | B13: gpt-5.4-mini | C13: substantive_comment | D13: substantive_comment | E13: 0 | F13: Support with Changes | G13: lng_terminal | H13: resident | I13: KY | J13: southwest | K13: cultural_historic | L13: other|other
... A241: 2967 | B241: gpt-5.4-mini | C241: agency_submission | D241: agency_submission | E241: 0 | F241: Neutral | G241: natural_gas_pipeline | H241: government | I241: OK | J241: south_central | K241: public_process | L241: cultural_historic

Sheet claude-sonnet-4-6
A1: pdf_id | B1: model | C1: llm_document_type | D1: llm_model_document_type | E1: llm_doctype_mismatch | F1: llm_support_label | G1: llm_project_type | H1: llm_commenter_type | I1: llm_project_state | J1: llm_project_region | K1: llm_feedback_theme_primary | L1: llm_feedback_theme_tags
A2: 138 | B2: claude-sonnet-4-6 | C2: substantive_comment | D2: substantive_comment | E2: 0 | F2: Support with Changes | G2: market_rate | H2: business | I2: NM | J2: southwest | K2: economics_jobs | L2: economics_jobs|public_process
A3: 241 | B3: claude-sonnet-4-6 | C3: agency_submission | D3: agency_submission | E3: 0 | F3: Support with Changes | G3: hydropower | H3: government | I3: WY | J3: northwest | K3: wildlife_ecosystem | L3: wildlife_ecosystem|water_impacts|public_process
A4: 259 | B4: claude-sonnet-4-6 | C4: substantive_comment | D4: substantive_comment | E4: 0 | F4: support | G4: market_rate | H4: business | I4: IL | J4: midwest | K4: climate_energy | L4: climate_energy|economics_jobs|public_process
A5: 264 | B5: claude-sonnet-4-6 | C5: agency_submission | D5: agency_submission | E5: 0 | F5: oppose | G5: hydropower | H5: government | I5: MI | J5: midwest | K5: wildlife_ecosystem | L5: wildlife_ecosystem|recreation_tourism|water_impacts|public_process
A6: 273 | B6: claude-sonnet-4-6 | C6: agency_submission | D6: agency_submission | E6: 0 | F6: Support with Changes | G6: hydropower | H6: government | I6: MO | J6: midwest | K6: cultural_historic | L6: cultural_historic|public_process
A7: 383 | B7: claude-sonnet-4-6 | C7: agency_submission | D7: agency_submission | E7: 0 | F7: Support with Changes | G7: hydropower | H7: government | I7: ME | J7: northeast | K7: wildlife_ecosystem | L7: wildlife_ecosystem|water_impacts|public_process
A8: 416 | B8: claude-sonnet-4-6 | C8: agency_submission | D8: agency_submission | E8: 0 | F8: Support with Changes | G8: hydropower | H8: government | I8: OR | J8: northwest | K8: water_impacts | L8: water_impacts|wildlife_ecosystem|public_process
A9: 474 | B9: claude-sonnet-4-6 | C9: agency_submission | D9: agency_submission | E9: 0 | F9: support | G9: hydropower | H9: government | I9: CA | J9: southwest | K9: cultural_historic | L9: cultural_historic|public_process
A10: 516 | B10: claude-sonnet-4-6 | C10: agency_submission | D10: agency_submission | E10: 0 | F10: Support with Changes | G10: hydropower | H10: government | I10: CT | J10: northeast | K10: wildlife_ecosystem | L10: wildlife_ecosystem|water_impacts|public_process
A11: 729 | B11: claude-sonnet-4-6 | C11: substantive_comment | D11: procedural_filing | E11: 1 | F11: Neutral | G11: electric_transmission | H11: business | I11: Unknown | J11: unknown | K11: climate_energy | L11: climate_energy|economics_jobs|grid_reliability
A12: 761 | B12: claude-sonnet-4-6 | C12: substantive_comment | D12: substantive_comment | E12: 0 | F12: support | G12: market_rate | H12: business | I12: FL | J12: southeast | K12: economics_jobs | L12: economics_jobs|grid_reliability
A13: 777 | B13: claude-sonnet-4-6 | C13: substantive_comment | D13: substantive_comment | E13: 0 | F13: oppose | G13: lng_terminal | H13: nonprofit | I13: LA | J13: south_central | K13: wildlife_ecosystem | L13: wildlife_ecosystem|water_impacts|economics_jobs|public_process
... A241: 10239 | B241: claude-sonnet-4-6 | C241: substantive_comment | D241: substantive_comment | E241: 0 | F241: support | G241: natural_gas_pipeline | H241: resident | I241: Virginia | J241: southeast | K241: economics_jobs | L241: economics_jobs|climate_energy|grid_reliability

Sheet Hand Coded
A1: pdf_id | B1: llm_support_label | C1: Feedback Theme | D1: Project Type | E1: Commenter Type | F1: Project State | G1: Project Region
A2: 138 | B2: Support with Changes | C2: public_process | D2: market_rate | E2: business | F2: Unknown | G2: Unknown
A3: 241 | B3: Support with Changes | C3: wildlife_ecosystem | D3: hydropower | E3: government | F3: WY | G3: northwest
A4: 259 | B4: Neutral | C4: public_process | D4: market_rate | E4: business | F4: Unknown | G4: Unknown
A5: 264 | B5: Oppose | C5: wildlife_ecosystem | D5: hydropower | E5: government | F5: MI | G5: midwest
A6: 273 | B6: Neutral | C6: public_process | D6: hydropower | E6: government | F6: Unknown | G6: Unknown
A7: 383 | B7: Support with Changes | C7: wildlife_ecosystem | D7: hydropower | E7: government | F7: ME | G7: northeast
A8: 416 | B8: Support with Changes | C8: water_impacts | D8: hydropower | E8: government | F8: OR | G8: northwest
A9: 474 | B9: Neutral | C9: public_process | D9: hydropower | E9: government | F9: CA | G9: southwest
A10: 516 | B10: Support with Changes | C10: wildlife_ecosystem | D10: hydropower | E10: government | F10: CT | G10: northeast
A11: 729 | B11: Neutral | C11: other | D11: grid_reliability | E11: business | F11: Unknown | G11: Unknown
A12: 761 | B12: Support | C12: economics_jobs | D12: natural_gas_pipeline | E12: business | F12: FL | G12: southeast
A13: 779 | B13: Oppose | C13: water_impacts | D13: natural_gas_pipeline | E13: nonprofit | F13: MD | G13: southeast
... A218: 6550 | B218: Oppose | C218: property_rights | D218: natural_gas_pipeline | E218: resident | F218: NY | G218: Northeast
A219: 6552 | B219: Neutral | C219: grid_reliability | D219: natural_gas_pipeline | E219: organization
A220: 6563 | B220: Support | C220: public_process | D220: natural_gas_pipeline | E220: business | F220: multiple states
A221: 6588 | B221: Neutral | C221: property_rights | D221: natural_gas_pipeline | E221: resident | F221: NY | G221: Northeast
A222: 6601 | B222: Neutral | C222: grid_reliability | D222: electric_transmission | E222: organization | F222: multiple states
A223: 6619 | B223: Support | C223: public_process | D223: natural_gas_pipeline | E223: organziation | F223: multiple states
A224: 6629 | B224: Support | C224: public_process | D224: electric_transmission | E224: organization | F224: multiple states
A225: 6737 | B225: Oppose | C225: public_process | D225: natural_gas_pipeline | E225: resident | F225: NY | G225: Northeast
A226: 6929 | B226: Oppose | C226: hydropower | D226: natural_gas_pipeline | E226: government | F226: MI | G226: Midwest
A227: 6988 | B227: Support | C227: wildlife_ecosystem | D227: hydropower | E227: organization | F227: VA | G227: Southeast
A228: 7256 | B228: Support | C228: wildlife_ecosystem | D228: hydropower | E228: organization | F228: VA | G228: Southeast
A229: 7264 | B229: Oppose | C229: history | D229: natural_gas_pipeline | E229: resident | F229: KY | G229: Southeast
A230: 7289 | B230: Oppose | C230: wildlife_ecosystem | D230: hydropower | E230: government | F230: VA | G230: Southeast
A231: 7316 | B231: Oppose | C231: public_process | D231: natural_gas_pipeline | E231: resident | F231: NY | G231: Northeast
A232: 6955 | B232: Oppose | C232: public_process | D232: natural_gas_pipeline | E232: organization | F232: NY | G232: Northeast
A233: 4746 | B233: Support | C233: economics_jobs | D233: natural_gas_pipeline | E233: organization | F233: KY | G233: Southeast
A234: 1485 | B234: Oppose | C234: wildlife_ecosystem | D234: natural_gas_pipeline | E234: organization | G234: Midwest
A235: 9768 | B235: Oppose | C235: wildlife_ecosystem | D235: hydropower | E235: resident | F235: WY | G235: West

Sheet Jess
A1: pdf_id | B1: llm_support_level (Sentiment/Support Level) | C1: Feedback Theme | D1: Project Type | E1: Commenter Type | F1: Project State | G1: Project Region
A2: 5178 | B2: Oppose | C2: water_impacts | D2: natural_gas_pipeline | E2: government | F2: NY | G2: Northeast
A3: 5185 | B3: Oppose | C3: public_process | D3: natural_gas_pipeline | E3: resident | F3: NY | G3: Northeast
A4: 5264 | B4: Neutral | C4: water_impacts | D4: hydropower | E4: government | F4: PA | G4: Northeast
A5: 5265 | B5: Neutral | C5: wildlife_ecosystem | D5: hydropower | E5: government | F5: PA | G5: Northeast
A6: 5300 | B6: Oppose | C6: wildlife_ecosystem | D6: natural_gas_pipeline | E6: resident | F6: NY | G6: Northeast
A7: 5312 | B7: Oppose | C7: wildlife_ecosystem | D7: natural_gas_pipeline | E7: resident | F7: NY | G7: Northeast
A8: 5331 | B8: Oppose | C8: property_rights | D8: natural_gas_pipeline | E8: resident | F8: NY | G8: Northeast
A9: 5338 | B9: Support | C9: grid_reliability | D9: electric_transmission | E9: organization | F9: NC | G9: Southeast
A10: 5344 | B10: Oppose | C10: public_process | D10: natural_gas_pipeline | E10: resident | F10: NY | G10: Northeast
A11: 5371 | B11: Oppose | C11: public_process | D11: natural_gas_pipeline | E11: resident | F11: NY | G11: Northeast
A12: 5518 | B12: Oppose | C12: water_impacts | D12: natural_gas_pipeline | E12: resident | F12: NY | G12: Northeast
A13: 5661 | B13: Oppose | C13: electric_transmission | D13: other | E13: business | F13: CA | G13: Southwest
... A38: 6550 | B38: Neutral | C38: property_rights | D38: natural_gas_pipeline | E38: resident | F38: NY | G38: Northeast
A39: 6552 | B39: Neutral | C39: grid_reliability | D39: natural_gas_pipeline | E39: organization
A40: 6563 | B40: Support | C40: public_process | D40: natural_gas_pipeline | E40: business | F40: multiple states
A41: 6588 | B41: Neutral | C41: property_rights | D41: natural_gas_pipeline | E41: resident | F41: NY | G41: Northeast
A42: 6601 | B42: Neutral | C42: grid_reliability | D42: electric_transmission | E42: organization | F42: multiple states
A43: 6619 | B43: Support | C43: public_process | D43: natural_gas_pipeline | E43: organziation | F43: multiple states
A44: 6629 | B44: Support | C44: public_process | D44: electric_transmission | E44: organization | F44: multiple states
A45: 6737 | B45: Oppose | C45: public_process | D45: natural_gas_pipeline | E45: resident | F45: NY | G45: Northeast
A46: 6929 | B46: Oppose | C46: hydropower | D46: natural_gas_pipeline | E46: government | F46: MI | G46: Midwest
A47: 6988 | B47: Support | C47: wildlife_ecosystem | D47: hydropower | E47: organization | F47: VA | G47: Southeast
A48: 7256 | B48: Support | C48: wildlife_ecosystem | D48: hydropower | E48: organization | F48: VA | G48: Southeast
A49: 7264 | B49: Oppose | C49: history | D49: natural_gas_pipeline | E49: resident | F49: KY | G49: Southeast
A50: 7289 | B50: Oppose | C50: wildlife_ecosystem | D50: hydropower | E50: government | F50: VA | G50: Southeast
A51: 7316 | B51: Oppose | C51: public_process | D51: natural_gas_pipeline | E51: resident | F51: NY | G51: Northeast
A52: 6955 | B52: Oppose | C52: public_process | D52: natural_gas_pipeline | E52: organization | F52: NY | G52: Northeast
A53: 4746 | B53: Support | C53: economics_jobs | D53: natural_gas_pipeline | E53: organization | F53: KY | G53: Southeast
A54: 1485 | B54: Oppose | C54: wildlife_ecosystem | D54: natural_gas_pipeline | E54: organization | G54: Midwest
A55: 9768 | B55: Oppose | C55: wildlife_ecosystem | D55: hydropower | E55: resident | F55: WY | G55: West
A56: 8159
A57: 10182
A58: 5296
A59: 777
A60: 10168
A61: 3522

Sheet Hand Code Off
A1: pdf_id | B1: Jess - Support Label | C1: HC - Support Label | D1: Support Match? | E1: Jess - Feedback Theme | F1: HC - Feedback Theme | G1: Theme Match? | H1: Jess - Project Type | I1: HC - Project Type | J1: Type Match? | K1: Jess - Commenter Type | L1: HC - Commenter Type | M1: Commenter Match? | N1: Jess - State | O1: HC - State | P1: State Match? | Q1: Jess - Region | R1: HC - Region | S1: Region Match? | T1: # Mismatches | U1: NEEDS REVIEW?
A2: =Jess!A2 -> 5178 | B2: =Jess!B2 -> Oppose | C2: =IFERROR(_xlfn.XLOOKUP(A2,'Hand Coded'!A:A,'Hand Coded'!B:B),"NOT FOUND") -> Oppose | D2: =IF(OR(C2="NOT FOUND",B2=""),"N/A",IF(LOWER(B2)=LOWER(C2),"✓","✗")) -> ✓ | E2: =Jess!C2 -> water_impacts | F2: =IFERROR(_xlfn.XLOOKUP(A2,'Hand Coded'!A:A,'Hand Coded'!C:C),"NOT FOUND") -> water_impacts | G2: =IF(OR(F2="NOT FOUND",E2=""),"N/A",IF(LOWER(E2)=LOWER(F2),"✓","✗")) -> ✓ | H2: =Jess!D2 -> natural_gas_pipeline | I2: =IFERROR(_xlfn.XLOOKUP(A2,'Hand Coded'!A:A,'Hand Coded'!D:D),"NOT FOUND") -> natural_gas_pipeline | J2: =IF(OR(I2="NOT FOUND",H2=""),"N/A",IF(LOWER(H2)=LOWER(I2),"✓","✗")) -> ✓ | K2: =Jess!E2 -> government | L2: =IFERROR(_xlfn.XLOOKUP(A2,'Hand Coded'!A:A,'Hand Coded'!E:E),"NOT FOUND") -> government | M2: =IF(OR(L2="NOT FOUND",K2=""),"N/A",IF(LOWER(K2)=LOWER(L2),"✓","✗")) -> ✓ | N2: =Jess!F2 -> NY | O2: =IFERROR(_xlfn.XLOOKUP(A2,'Hand Coded'!A:A,'Hand Coded'!F:F),"NOT FOUND") -> NY | P2: =IF(OR(O2="NOT FOUND",N2=""),"N/A",IF(LOWER(N2)=LOWER(O2),"✓","✗")) -> ✓ | Q2: =Jess!G2 -> Northeast | R2: =IFERROR(_xlfn.XLOOKUP(A2,'Hand Coded'!A:A,'Hand Coded'!G:G),"NOT FOUND") -> Northeast | S2: =IF(OR(R2="NOT FOUND",Q2=""),"N/A",IF(LOWER(Q2)=LOWER(R2),"✓","✗")) -> ✓ | T2: =COUNTIF(D2,"✗")+COUNTIF(G2,"✗")+COUNTIF(J2,"✗")+COUNTIF(M2,"✗")+COUNTIF(P2,"✗")+COUNTIF(S2,"✗") -> 0 | U2: =IF(T2>0,"⚠ REVIEW",IF(COUNTIF(D2:S2,"N/A")=6,"NOT IN HC","OK")) -> OK
A3: =Jess!A3 -> 5185 | B3: =Jess!B3 -> Oppose | C3: =IFERROR(_xlfn.XLOOKUP(A3,'Hand Coded'!A:A,'Hand Coded'!B:B),"NOT FOUND") -> Oppose | D3: =IF(OR(C3="NOT FOUND",B3=""),"N/A",IF(LOWER(B3)=LOWER(C3),"✓","✗")) -> ✓ | E3: =Jess!C3 -> public_process | F3: =IFERROR(_xlfn.XLOOKUP(A3,'Hand Coded'!A:A,'Hand Coded'!C:C),"NOT FOUND") -> public_process | G3: =IF(OR(F3="NOT FOUND",E3=""),"N/A",IF(LOWER(E3)=LOWER(F3),"✓","✗")) -> ✓ | H3: =Jess!D3 -> natural_gas_pipeline | I3: =IFERROR(_xlfn.XLOOKUP(A3,'Hand Coded'!A:A,'Hand Coded'!D:D),"NOT FOUND") -> natural_gas_pipeline | J3: =IF(OR(I3="NOT FOUND",H3=""),"N/A",IF(LOWER(H3)=LOWER(I3),"✓","✗")) -> ✓ | K3: =Jess!E3 -> resident | L3: =IFERROR(_xlfn.XLOOKUP(A3,'Hand Coded'!A:A,'Hand Coded'!E:E),"NOT FOUND") -> resident | M3: =IF(OR(L3="NOT FOUND",K3=""),"N/A",IF(LOWER(K3)=LOWER(L3),"✓","✗")) -> ✓ | N3: =Jess!F3 -> NY | O3: =IFERROR(_xlfn.XLOOKUP(A3,'Hand Coded'!A:A,'Hand Coded'!F:F),"NOT FOUND") -> NY | P3: =IF(OR(O3="NOT FOUND",N3=""),"N/A",IF(LOWER(N3)=LOWER(O3),"✓","✗")) -> ✓ | Q3: =Jess!G3 -> Northeast | R3: =IFERROR(_xlfn.XLOOKUP(A3,'Hand Coded'!A:A,'Hand Coded'!G:G),"NOT FOUND") -> Northeast | S3: =IF(OR(R3="NOT FOUND",Q3=""),"N/A",IF(LOWER(Q3)=LOWER(R3),"✓","✗")) -> ✓ | T3: =COUNTIF(D3,"✗")+COUNTIF(G3,"✗")+COUNTIF(J3,"✗")+COUNTIF(M3,"✗")+COUNTIF(P3,"✗")+COUNTIF(S3,"✗") -> 0 | U3: =IF(T3>0,"⚠ REVIEW",IF(COUNTIF(D3:S3,"N/A")=6,"NOT IN HC","OK")) -> OK
A4: =Jess!A4 -> 5264 | B4: =Jess!B4 -> Neutral | C4: =IFERROR(_xlfn.XLOOKUP(A4,'Hand Coded'!A:A,'Hand Coded'!B:B),"NOT FOUND") -> Support with Changes | D4: =IF(OR(C4="NOT FOUND",B4=""),"N/A",IF(LOWER(B4)=LOWER(C4),"✓","✗")) -> ✗ | E4: =Jess!C4 -> water_impacts | F4: =IFERROR(_xlfn.XLOOKUP(A4,'Hand Coded'!A:A,'Hand Coded'!C:C),"NOT FOUND") -> water_impacts | G4: =IF(OR(F4="NOT FOUND",E4=""),"N/A",IF(LOWER(E4)=LOWER(F4),"✓","✗")) -> ✓ | H4: =Jess!D4 -> hydropower | I4: =IFERROR(_xlfn.XLOOKUP(A4,'Hand Coded'!A:A,'Hand Coded'!D:D),"NOT FOUND") -> hydropower | J4: =IF(OR(I4="NOT FOUND",H4=""),"N/A",IF(LOWER(H4)=LOWER(I4),"✓","✗")) -> ✓ | K4: =Jess!E4 -> government | L4: =IFERROR(_xlfn.XLOOKUP(A4,'Hand Coded'!A:A,'Hand Coded'!E:E),"NOT FOUND") -> government | M4: =IF(OR(L4="NOT FOUND",K4=""),"N/A",IF(LOWER(K4)=LOWER(L4),"✓","✗")) -> ✓ | N4: =Jess!F4 -> PA | O4: =IFERROR(_xlfn.XLOOKUP(A4,'Hand Coded'!A:A,'Hand Coded'!F:F),"NOT FOUND") -> PA | P4: =IF(OR(O4="NOT FOUND",N4=""),"N/A",IF(LOWER(N4)=LOWER(O4),"✓","✗")) -> ✓ | Q4: =Jess!G4 -> Northeast | R4: =IFERROR(_xlfn.XLOOKUP(A4,'Hand Coded'!A:A,'Hand Coded'!G:G),"NOT FOUND") -> Northeast | S4: =IF(OR(R4="NOT FOUND",Q4=""),"N/A",IF(LOWER(Q4)=LOWER(R4),"✓","✗")) -> ✓ | T4: =COUNTIF(D4,"✗")+COUNTIF(G4,"✗")+COUNTIF(J4,"✗")+COUNTIF(M4,"✗")+COUNTIF(P4,"✗")+COUNTIF(S4,"✗") -> 1 | U4: =IF(T4>0,"⚠ REVIEW",IF(COUNTIF(D4:S4,"N/A")=6,"NOT IN HC","OK")) -> ⚠ REVIEW
A5: =Jess!A5 -> 5265 | B5: =Jess!B5 -> Neutral | C5: =IFERROR(_xlfn.XLOOKUP(A5,'Hand Coded'!A:A,'Hand Coded'!B:B),"NOT FOUND") -> Support with Changes | D5: =IF(OR(C5="NOT FOUND",B5=""),"N/A",IF(LOWER(B5)=LOWER(C5),"✓","✗")) -> ✗ | E5: =Jess!C5 -> wildlife_ecosystem | F5: =IFERROR(_xlfn.XLOOKUP(A5,'Hand Coded'!A:A,'Hand Coded'!C:C),"NOT FOUND") -> wildlife_ecosystem | G5: =IF(OR(F5="NOT FOUND",E5=""),"N/A",IF(LOWER(E5)=LOWER(F5),"✓","✗")) -> ✓ | H5: =Jess!D5 -> hydropower | I5: =IFERROR(_xlfn.XLOOKUP(A5,'Hand Coded'!A:A,'Hand Coded'!D:D),"NOT FOUND") -> hydropower | J5: =IF(OR(I5="NOT FOUND",H5=""),"N/A",IF(LOWER(H5)=LOWER(I5),"✓","✗")) -> ✓ | K5: =Jess!E5 -> government | L5: =IFERROR(_xlfn.XLOOKUP(A5,'Hand Coded'!A:A,'Hand Coded'!E:E),"NOT FOUND") -> government | M5: =IF(OR(L5="NOT FOUND",K5=""),"N/A",IF(LOWER(K5)=LOWER(L5),"✓","✗")) -> ✓ | N5: =Jess!F5 -> PA | O5: =IFERROR(_xlfn.XLOOKUP(A5,'Hand Coded'!A:A,'Hand Coded'!F:F),"NOT FOUND") -> PA | P5: =IF(OR(O5="NOT FOUND",N5=""),"N/A",IF(LOWER(N5)=LOWER(O5),"✓","✗")) -> ✓ | Q5: =Jess!G5 -> Northeast | R5: =IFERROR(_xlfn.XLOOKUP(A5,'Hand Coded'!A:A,'Hand Coded'!G:G),"NOT FOUND") -> Northeast | S5: =IF(OR(R5="NOT FOUND",Q5=""),"N/A",IF(LOWER(Q5)=LOWER(R5),"✓","✗")) -> ✓ | T5: =COUNTIF(D5,"✗")+COUNTIF(G5,"✗")+COUNTIF(J5,"✗")+COUNTIF(M5,"✗")+COUNTIF(P5,"✗")+COUNTIF(S5,"✗") -> 1 | U5: =IF(T5>0,"⚠ REVIEW",IF(COUNTIF(D5:S5,"N/A")=6,"NOT IN HC","OK")) -> ⚠ REVIEW
A6: =Jess!A6 -> 5300 | B6: =Jess!B6 -> Oppose | C6: =IFERROR(_xlfn.XLOOKUP(A6,'Hand Coded'!A:A,'Hand Coded'!B:B),"NOT FOUND") -> Oppose | D6: =IF(OR(C6="NOT FOUND",B6=""),"N/A",IF(LOWER(B6)=LOWER(C6),"✓","✗")) -> ✓ | E6: =Jess!C6 -> wildlife_ecosystem | F6: =IFERROR(_xlfn.XLOOKUP(A6,'Hand Coded'!A:A,'Hand Coded'!C:C),"NOT FOUND") -> wildlife_ecosystem | G6: =IF(OR(F6="NOT FOUND",E6=""),"N/A",IF(LOWER(E6)=LOWER(F6),"✓","✗")) -> ✓ | H6: =Jess!D6 -> natural_gas_pipeline | I6: =IFERROR(_xlfn.XLOOKUP(A6,'Hand Coded'!A:A,'Hand Coded'!D:D),"NOT FOUND") -> natural_gas_pipeline | J6: =IF(OR(I6="NOT FOUND",H6=""),"N/A",IF(LOWER(H6)=LOWER(I6),"✓","✗")) -> ✓ | K6: =Jess!E6 -> resident | L6: =IFERROR(_xlfn.XLOOKUP(A6,'Hand Coded'!A:A,'Hand Coded'!E:E),"NOT FOUND") -> resident | M6: =IF(OR(L6="NOT FOUND",K6=""),"N/A",IF(LOWER(K6)=LOWER(L6),"✓","✗")) -> ✓ | N6: =Jess!F6 -> NY | O6: =IFERROR(_xlfn.XLOOKUP(A6,'Hand Coded'!A:A,'Hand Coded'!F:F),"NOT FOUND") -> NY | P6: =IF(OR(O6="NOT FOUND",N6=""),"N/A",IF(LOWER(N6)=LOWER(O6),"✓","✗")) -> ✓ | Q6: =Jess!G6 -> Northeast | R6: =IFERROR(_xlfn.XLOOKUP(A6,'Hand Coded'!A:A,'Hand Coded'!G:G),"NOT FOUND") -> Northeast | S6: =IF(OR(R6="NOT FOUND",Q6=""),"N/A",IF(LOWER(Q6)=LOWER(R6),"✓","✗")) -> ✓ | T6: =COUNTIF(D6,"✗")+COUNTIF(G6,"✗")+COUNTIF(J6,"✗")+COUNTIF(M6,"✗")+COUNTIF(P6,"✗")+COUNTIF(S6,"✗") -> 0 | U6: =IF(T6>0,"⚠ REVIEW",IF(COUNTIF(D6:S6,"N/A")=6,"NOT IN HC","OK")) -> OK
A7: =Jess!A7 -> 5312 | B7: =Jess!B7 -> Oppose | C7: =IFERROR(_xlfn.XLOOKUP(A7,'Hand Coded'!A:A,'Hand Coded'!B:B),"NOT FOUND") -> Oppose | D7: =IF(OR(C7="NOT FOUND",B7=""),"N/A",IF(LOWER(B7)=LOWER(C7),"✓","✗")) -> ✓ | E7: =Jess!C7 -> wildlife_ecosystem | F7: =IFERROR(_xlfn.XLOOKUP(A7,'Hand Coded'!A:A,'Hand Coded'!C:C),"NOT FOUND") -> wildlife_ecosystem | G7: =IF(OR(F7="NOT FOUND",E7=""),"N/A",IF(LOWER(E7)=LOWER(F7),"✓","✗")) -> ✓ | H7: =Jess!D7 -> natural_gas_pipeline | I7: =IFERROR(_xlfn.XLOOKUP(A7,'Hand Coded'!A:A,'Hand Coded'!D:D),"NOT FOUND") -> natural_gas_pipeline | J7: =IF(OR(I7="NOT FOUND",H7=""),"N/A",IF(LOWER(H7)=LOWER(I7),"✓","✗")) -> ✓ | K7: =Jess!E7 -> resident | L7: =IFERROR(_xlfn.XLOOKUP(A7,'Hand Coded'!A:A,'Hand Coded'!E:E),"NOT FOUND") -> resident | M7: =IF(OR(L7="NOT FOUND",K7=""),"N/A",IF(LOWER(K7)=LOWER(L7),"✓","✗")) -> ✓ | N7: =Jess!F7 -> NY | O7: =IFERROR(_xlfn.XLOOKUP(A7,'Hand Coded'!A:A,'Hand Coded'!F:F),"NOT FOUND") -> NY | P7: =IF(OR(O7="NOT FOUND",N7=""),"N/A",IF(LOWER(N7)=LOWER(O7),"✓","✗")) -> ✓ | Q7: =Jess!G7 -> Northeast | R7: =IFERROR(_xlfn.XLOOKUP(A7,'Hand Coded'!A:A,'Hand Coded'!G:G),"NOT FOUND") -> Northeast | S7: =IF(OR(R7="NOT FOUND",Q7=""),"N/A",IF(LOWER(Q7)=LOWER(R7),"✓","✗")) -> ✓ | T7: =COUNTIF(D7,"✗")+COUNTIF(G7,"✗")+COUNTIF(J7,"✗")+COUNTIF(M7,"✗")+COUNTIF(P7,"✗")+COUNTIF(S7,"✗") -> 0 | U7: =IF(T7>0,"⚠ REVIEW",IF(COUNTIF(D7:S7,"N/A")=6,"NOT IN HC","OK")) -> OK
A8: =Jess!A8 -> 5331 | B8: =Jess!B8 -> Oppose | C8: =IFERROR(_xlfn.XLOOKUP(A8,'Hand Coded'!A:A,'Hand Coded'!B:B),"NOT FOUND") -> Oppose | D8: =IF(OR(C8="NOT FOUND",B8=""),"N/A",IF(LOWER(B8)=LOWER(C8),"✓","✗")) -> ✓ | E8: =Jess!C8 -> property_rights | F8: =IFERROR(_xlfn.XLOOKUP(A8,'Hand Coded'!A:A,'Hand Coded'!C:C),"NOT FOUND") -> property_rights | G8: =IF(OR(F8="NOT FOUND",E8=""),"N/A",IF(LOWER(E8)=LOWER(F8),"✓","✗")) -> ✓ | H8: =Jess!D8 -> natural_gas_pipeline | I8: =IFERROR(_xlfn.XLOOKUP(A8,'Hand Coded'!A:A,'Hand Coded'!D:D),"NOT FOUND") -> natural_gas_pipeline | J8: =IF(OR(I8="NOT FOUND",H8=""),"N/A",IF(LOWER(H8)=LOWER(I8),"✓","✗")) -> ✓ | K8: =Jess!E8 -> resident | L8: =IFERROR(_xlfn.XLOOKUP(A8,'Hand Coded'!A:A,'Hand Coded'!E:E),"NOT FOUND") -> resident | M8: =IF(OR(L8="NOT FOUND",K8=""),"N/A",IF(LOWER(K8)=LOWER(L8),"✓","✗")) -> ✓ | N8: =Jess!F8 -> NY | O8: =IFERROR(_xlfn.XLOOKUP(A8,'Hand Coded'!A:A,'Hand Coded'!F:F),"NOT FOUND") -> NY | P8: =IF(OR(O8="NOT FOUND",N8=""),"N/A",IF(LOWER(N8)=LOWER(O8),"✓","✗")) -> ✓ | Q8: =Jess!G8 -> Northeast | R8: =IFERROR(_xlfn.XLOOKUP(A8,'Hand Coded'!A:A,'Hand Coded'!G:G),"NOT FOUND") -> Northeast | S8: =IF(OR(R8="NOT FOUND",Q8=""),"N/A",IF(LOWER(Q8)=LOWER(R8),"✓","✗")) -> ✓ | T8: =COUNTIF(D8,"✗")+COUNTIF(G8,"✗")+COUNTIF(J8,"✗")+COUNTIF(M8,"✗")+COUNTIF(P8,"✗")+COUNTIF(S8,"✗") -> 0 | U8: =IF(T8>0,"⚠ REVIEW",IF(COUNTIF(D8:S8,"N/A")=6,"NOT IN HC","OK")) -> OK
A9: =Jess!A9 -> 5338 | B9: =Jess!B9 -> Support | C9: =IFERROR(_xlfn.XLOOKUP(A9,'Hand Coded'!A:A,'Hand Coded'!B:B),"NOT FOUND") -> Support | D9: =IF(OR(C9="NOT FOUND",B9=""),"N/A",IF(LOWER(B9)=LOWER(C9),"✓","✗")) -> ✓ | E9: =Jess!C9 -> grid_reliability | F9: =IFERROR(_xlfn.XLOOKUP(A9,'Hand Coded'!A:A,'Hand Coded'!C:C),"NOT FOUND") -> grid_reliability | G9: =IF(OR(F9="NOT FOUND",E9=""),"N/A",IF(LOWER(E9)=LOWER(F9),"✓","✗")) -> ✓ | H9: =Jess!D9 -> electric_transmission | I9: =IFERROR(_xlfn.XLOOKUP(A9,'Hand Coded'!A:A,'Hand Coded'!D:D),"NOT FOUND") -> grid_reliability | J9: =IF(OR(I9="NOT FOUND",H9=""),"N/A",IF(LOWER(H9)=LOWER(I9),"✓","✗")) -> ✗ | K9: =Jess!E9 -> organization | L9: =IFERROR(_xlfn.XLOOKUP(A9,'Hand Coded'!A:A,'Hand Coded'!E:E),"NOT FOUND") -> organization | M9: =IF(OR(L9="NOT FOUND",K9=""),"N/A",IF(LOWER(K9)=LOWER(L9),"✓","✗")) -> ✓ | N9: =Jess!F9 -> NC | O9: =IFERROR(_xlfn.XLOOKUP(A9,'Hand Coded'!A:A,'Hand Coded'!F:F),"NOT FOUND") -> NC | P9: =IF(OR(O9="NOT FOUND",N9=""),"N/A",IF(LOWER(N9)=LOWER(O9),"✓","✗")) -> ✓ | Q9: =Jess!G9 -> Southeast | R9: =IFERROR(_xlfn.XLOOKUP(A9,'Hand Coded'!A:A,'Hand Coded'!G:G),"NOT FOUND") -> Southeast | S9: =IF(OR(R9="NOT FOUND",Q9=""),"N/A",IF(LOWER(Q9)=LOWER(R9),"✓","✗")) -> ✓ | T9: =COUNTIF(D9,"✗")+COUNTIF(G9,"✗")+COUNTIF(J9,"✗")+COUNTIF(M9,"✗")+COUNTIF(P9,"✗")+COUNTIF(S9,"✗") -> 1 | U9: =IF(T9>0,"⚠ REVIEW",IF(COUNTIF(D9:S9,"N/A")=6,"NOT IN HC","OK")) -> ⚠ REVIEW
A10: =Jess!A10 -> 5344 | B10: =Jess!B10 -> Oppose | C10: =IFERROR(_xlfn.XLOOKUP(A10,'Hand Coded'!A:A,'Hand Coded'!B:B),"NOT FOUND") -> Oppose | D10: =IF(OR(C10="NOT FOUND",B10=""),"N/A",IF(LOWER(B10)=LOWER(C10),"✓","✗")) -> ✓ | E10: =Jess!C10 -> public_process | F10: =IFERROR(_xlfn.XLOOKUP(A10,'Hand Coded'!A:A,'Hand Coded'!C:C),"NOT FOUND") -> public_process | G10: =IF(OR(F10="NOT FOUND",E10=""),"N/A",IF(LOWER(E10)=LOWER(F10),"✓","✗")) -> ✓ | H10: =Jess!D10 -> natural_gas_pipeline | I10: =IFERROR(_xlfn.XLOOKUP(A10,'Hand Coded'!A:A,'Hand Coded'!D:D),"NOT FOUND") -> natural_gas_pipeline | J10: =IF(OR(I10="NOT FOUND",H10=""),"N/A",IF(LOWER(H10)=LOWER(I10),"✓","✗")) -> ✓ | K10: =Jess!E10 -> resident | L10: =IFERROR(_xlfn.XLOOKUP(A10,'Hand Coded'!A:A,'Hand Coded'!E:E),"NOT FOUND") -> resident | M10: =IF(OR(L10="NOT FOUND",K10=""),"N/A",IF(LOWER(K10)=LOWER(L10),"✓","✗")) -> ✓ | N10: =Jess!F10 -> NY | O10: =IFERROR(_xlfn.XLOOKUP(A10,'Hand Coded'!A:A,'Hand Coded'!F:F),"NOT FOUND") -> NY | P10: =IF(OR(O10="NOT FOUND",N10=""),"N/A",IF(LOWER(N10)=LOWER(O10),"✓","✗")) -> ✓ | Q10: =Jess!G10 -> Northeast | R10: =IFERROR(_xlfn.XLOOKUP(A10,'Hand Coded'!A:A,'Hand Coded'!G:G),"NOT FOUND") -> Northeast | S10: =IF(OR(R10="NOT FOUND",Q10=""),"N/A",IF(LOWER(Q10)=LOWER(R10),"✓","✗")) -> ✓ | T10: =COUNTIF(D10,"✗")+COUNTIF(G10,"✗")+COUNTIF(J10,"✗")+COUNTIF(M10,"✗")+COUNTIF(P10,"✗")+COUNTIF(S10,"✗") -> 0 | U10: =IF(T10>0,"⚠ REVIEW",IF(COUNTIF(D10:S10,"N/A")=6,"NOT IN HC","OK")) -> OK
A11: =Jess!A11 -> 5371 | B11: =Jess!B11 -> Oppose | C11: =IFERROR(_xlfn.XLOOKUP(A11,'Hand Coded'!A:A,'Hand Coded'!B:B),"NOT FOUND") -> Oppose | D11: =IF(OR(C11="NOT FOUND",B11=""),"N/A",IF(LOWER(B11)=LOWER(C11),"✓","✗")) -> ✓ | E11: =Jess!C11 -> public_process | F11: =IFERROR(_xlfn.XLOOKUP(A11,'Hand Coded'!A:A,'Hand Coded'!C:C),"NOT FOUND") -> public_process | G11: =IF(OR(F11="NOT FOUND",E11=""),"N/A",IF(LOWER(E11)=LOWER(F11),"✓","✗")) -> ✓ | H11: =Jess!D11 -> natural_gas_pipeline | I11: =IFERROR(_xlfn.XLOOKUP(A11,'Hand Coded'!A:A,'Hand Coded'!D:D),"NOT FOUND") -> natural_gas_pipeline | J11: =IF(OR(I11="NOT FOUND",H11=""),"N/A",IF(LOWER(H11)=LOWER(I11),"✓","✗")) -> ✓ | K11: =Jess!E11 -> resident | L11: =IFERROR(_xlfn.XLOOKUP(A11,'Hand Coded'!A:A,'Hand Coded'!E:E),"NOT FOUND") -> resident | M11: =IF(OR(L11="NOT FOUND",K11=""),"N/A",IF(LOWER(K11)=LOWER(L11),"✓","✗")) -> ✓ | N11: =Jess!F11 -> NY | O11: =IFERROR(_xlfn.XLOOKUP(A11,'Hand Coded'!A:A,'Hand Coded'!F:F),"NOT FOUND") -> NY | P11: =IF(OR(O11="NOT FOUND",N11=""),"N/A",IF(LOWER(N11)=LOWER(O11),"✓","✗")) -> ✓ | Q11: =Jess!G11 -> Northeast | R11: =IFERROR(_xlfn.XLOOKUP(A11,'Hand Coded'!A:A,'Hand Coded'!G:G),"NOT FOUND") -> Northeast | S11: =IF(OR(R11="NOT FOUND",Q11=""),"N/A",IF(LOWER(Q11)=LOWER(R11),"✓","✗")) -> ✓ | T11: =COUNTIF(D11,"✗")+COUNTIF(G11,"✗")+COUNTIF(J11,"✗")+COUNTIF(M11,"✗")+COUNTIF(P11,"✗")+COUNTIF(S11,"✗") -> 0 | U11: =IF(T11>0,"⚠ REVIEW",IF(COUNTIF(D11:S11,"N/A")=6,"NOT IN HC","OK")) -> OK
A12: =Jess!A12 -> 5518 | B12: =Jess!B12 -> Oppose | C12: =IFERROR(_xlfn.XLOOKUP(A12,'Hand Coded'!A:A,'Hand Coded'!B:B),"NOT FOUND") -> Oppose | D12: =IF(OR(C12="NOT FOUND",B12=""),"N/A",IF(LOWER(B12)=LOWER(C12),"✓","✗")) -> ✓ | E12: =Jess!C12 -> water_impacts | F12: =IFERROR(_xlfn.XLOOKUP(A12,'Hand Coded'!A:A,'Hand Coded'!C:C),"NOT FOUND") -> water_impacts | G12: =IF(OR(F12="NOT FOUND",E12=""),"N/A",IF(LOWER(E12)=LOWER(F12),"✓","✗")) -> ✓ | H12: =Jess!D12 -> natural_gas_pipeline | I12: =IFERROR(_xlfn.XLOOKUP(A12,'Hand Coded'!A:A,'Hand Coded'!D:D),"NOT FOUND") -> natural_gas_pipeline | J12: =IF(OR(I12="NOT FOUND",H12=""),"N/A",IF(LOWER(H12)=LOWER(I12),"✓","✗")) -> ✓ | K12: =Jess!E12 -> resident | L12: =IFERROR(_xlfn.XLOOKUP(A12,'Hand Coded'!A:A,'Hand Coded'!E:E),"NOT FOUND") -> resident | M12: =IF(OR(L12="NOT FOUND",K12=""),"N/A",IF(LOWER(K12)=LOWER(L12),"✓","✗")) -> ✓ | N12: =Jess!F12 -> NY | O12: =IFERROR(_xlfn.XLOOKUP(A12,'Hand Coded'!A:A,'Hand Coded'!F:F),"NOT FOUND") -> NY | P12: =IF(OR(O12="NOT FOUND",N12=""),"N/A",IF(LOWER(N12)=LOWER(O12),"✓","✗")) -> ✓ | Q12: =Jess!G12 -> Northeast | R12: =IFERROR(_xlfn.XLOOKUP(A12,'Hand Coded'!A:A,'Hand Coded'!G:G),"NOT FOUND") -> Northeast | S12: =IF(OR(R12="NOT FOUND",Q12=""),"N/A",IF(LOWER(Q12)=LOWER(R12),"✓","✗")) -> ✓ | T12: =COUNTIF(D12,"✗")+COUNTIF(G12,"✗")+COUNTIF(J12,"✗")+COUNTIF(M12,"✗")+COUNTIF(P12,"✗")+COUNTIF(S12,"✗") -> 0 | U12: =IF(T12>0,"⚠ REVIEW",IF(COUNTIF(D12:S12,"N/A")=6,"NOT IN HC","OK")) -> OK
A13: =Jess!A13 -> 5661 | B13: =Jess!B13 -> Oppose | C13: =IFERROR(_xlfn.XLOOKUP(A13,'Hand Coded'!A:A,'Hand Coded'!B:B),"NOT FOUND") -> Oppose | D13: =IF(OR(C13="NOT FOUND",B13=""),"N/A",IF(LOWER(B13)=LOWER(C13),"✓","✗")) -> ✓ | E13: =Jess!C13 -> electric_transmission | F13: =IFERROR(_xlfn.XLOOKUP(A13,'Hand Coded'!A:A,'Hand Coded'!C:C),"NOT FOUND") -> grid_reliability | G13: =IF(OR(F13="NOT FOUND",E13=""),"N/A",IF(LOWER(E13)=LOWER(F13),"✓","✗")) -> ✗ | H13: =Jess!D13 -> other | I13: =IFERROR(_xlfn.XLOOKUP(A13,'Hand Coded'!A:A,'Hand Coded'!D:D),"NOT FOUND") -> other | J13: =IF(OR(I13="NOT FOUND",H13=""),"N/A",IF(LOWER(H13)=LOWER(I13),"✓","✗")) -> ✓ | K13: =Jess!E13 -> business | L13: =IFERROR(_xlfn.XLOOKUP(A13,'Hand Coded'!A:A,'Hand Coded'!E:E),"NOT FOUND") -> business | M13: =IF(OR(L13="NOT FOUND",K13=""),"N/A",IF(LOWER(K13)=LOWER(L13),"✓","✗")) -> ✓ | N13: =Jess!F13 -> CA | O13: =IFERROR(_xlfn.XLOOKUP(A13,'Hand Coded'!A:A,'Hand Coded'!F:F),"NOT FOUND") -> CA | P13: =IF(OR(O13="NOT FOUND",N13=""),"N/A",IF(LOWER(N13)=LOWER(O13),"✓","✗")) -> ✓ | Q13: =Jess!G13 -> Southwest | R13: =IFERROR(_xlfn.XLOOKUP(A13,'Hand Coded'!A:A,'Hand Coded'!G:G),"NOT FOUND") -> Southwest | S13: =IF(OR(R13="NOT FOUND",Q13=""),"N/A",IF(LOWER(Q13)=LOWER(R13),"✓","✗")) -> ✓ | T13: =COUNTIF(D13,"✗")+COUNTIF(G13,"✗")+COUNTIF(J13,"✗")+COUNTIF(M13,"✗")+COUNTIF(P13,"✗")+COUNTIF(S13,"✗") -> 1 | U13: =IF(T13>0,"⚠ REVIEW",IF(COUNTIF(D13:S13,"N/A")=6,"NOT IN HC","OK")) -> ⚠ REVIEW
... A61: =Jess!A61 -> 3522 | B61: =Jess!B61 -> 0 | C61: =IFERROR(_xlfn.XLOOKUP(A61,'Hand Coded'!A:A,'Hand Coded'!B:B),"NOT FOUND") -> NOT FOUND | D61: =IF(OR(C61="NOT FOUND",B61=""),"N/A",IF(LOWER(B61)=LOWER(C61),"✓","✗")) -> N/A | E61: =Jess!C61 -> 0 | F61: =IFERROR(_xlfn.XLOOKUP(A61,'Hand Coded'!A:A,'Hand Coded'!C:C),"NOT FOUND") -> NOT FOUND | G61: =IF(OR(F61="NOT FOUND",E61=""),"N/A",IF(LOWER(E61)=LOWER(F61),"✓","✗")) -> N/A | H61: =Jess!D61 -> 0 | I61: =IFERROR(_xlfn.XLOOKUP(A61,'Hand Coded'!A:A,'Hand Coded'!D:D),"NOT FOUND") -> NOT FOUND | J61: =IF(OR(I61="NOT FOUND",H61=""),"N/A",IF(LOWER(H61)=LOWER(I61),"✓","✗")) -> N/A | K61: =Jess!E61 -> 0 | L61: =IFERROR(_xlfn.XLOOKUP(A61,'Hand Coded'!A:A,'Hand Coded'!E:E),"NOT FOUND") -> NOT FOUND | M61: =IF(OR(L61="NOT FOUND",K61=""),"N/A",IF(LOWER(K61)=LOWER(L61),"✓","✗")) -> N/A | N61: =Jess!F61 -> 0 | O61: =IFERROR(_xlfn.XLOOKUP(A61,'Hand Coded'!A:A,'Hand Coded'!F:F),"NOT FOUND") -> NOT FOUND | P61: =IF(OR(O61="NOT FOUND",N61=""),"N/A",IF(LOWER(N61)=LOWER(O61),"✓","✗")) -> N/A | Q61: =Jess!G61 -> 0 | R61: =IFERROR(_xlfn.XLOOKUP(A61,'Hand Coded'!A:A,'Hand Coded'!G:G),"NOT FOUND") -> NOT FOUND | S61: =IF(OR(R61="NOT FOUND",Q61=""),"N/A",IF(LOWER(Q61)=LOWER(R61),"✓","✗")) -> N/A | T61: =COUNTIF(D61,"✗")+COUNTIF(G61,"✗")+COUNTIF(J61,"✗")+COUNTIF(M61,"✗")+COUNTIF(P61,"✗")+COUNTIF(S61,"✗") -> 0 | U61: =IF(T61>0,"⚠ REVIEW",IF(COUNTIF(D61:S61,"N/A")=6,"NOT IN HC","OK")) -> NOT IN HC

Sheet Sentiment Analysis
A1: gemini-3.1-flash-lite-preview
A2: Manually Identified Stance | B2: Number Correct | C2: Total Manually Identified Entries | D2: Recall (%)
A3: Support | B3: {=SUMPRODUCT(('Hand Coded'!B$2:B$10000=A3)*(LOWER('Hand Coded'!B$2:B$10000)=LOWER(IFERROR(INDEX('gemini-3.1-flash-lite-preview'!F:F,MATCH('Hand Coded'!A$2:A$10000,'gemini-3.1-flash-lite-preview'!A:A,0)),""))))} -> 36 | C3: =COUNTIF('Hand Coded'!B:B,A3) -> 47 | D3: =IF(C3=0,"",B3/C3) -> 0.76595745
A4: Support with Changes | B4: {=SUMPRODUCT(('Hand Coded'!B$2:B$10000=A4)*(LOWER('Hand Coded'!B$2:B$10000)=LOWER(IFERROR(INDEX('gemini-3.1-flash-lite-preview'!F:F,MATCH('Hand Coded'!A$2:A$10000,'gemini-3.1-flash-lite-preview'!A:A,0)),""))))} -> 36 | C4: =COUNTIF('Hand Coded'!B:B,A4) -> 39 | D4: =IF(C4=0,"",B4/C4) -> 0.92307692
A5: Oppose | B5: {=SUMPRODUCT(('Hand Coded'!B$2:B$10000=A5)*(LOWER('Hand Coded'!B$2:B$10000)=LOWER(IFERROR(INDEX('gemini-3.1-flash-lite-preview'!F:F,MATCH('Hand Coded'!A$2:A$10000,'gemini-3.1-flash-lite-preview'!A:A,0)),""))))} -> 90 | C5: =COUNTIF('Hand Coded'!B:B,A5) -> 101 | D5: =IF(C5=0,"",B5/C5) -> 0.89108911
A6: Neutral | B6: {=SUMPRODUCT(('Hand Coded'!B$2:B$10000=A6)*(LOWER('Hand Coded'!B$2:B$10000)=LOWER(IFERROR(INDEX('gemini-3.1-flash-lite-preview'!F:F,MATCH('Hand Coded'!A$2:A$10000,'gemini-3.1-flash-lite-preview'!A:A,0)),""))))} -> 34 | C6: =COUNTIF('Hand Coded'!B:B,A6) -> 47 | D6: =IF(C6=0,"",B6/C6) -> 0.72340426
A7: Total | B7: =SUM(B3:B6) -> 196 | C7: =SUM(C3:C6) -> 234 | D7: =IF(C7=0,"",B7/C7) -> 0.83760684
A9: gpt-5.4-mini
A10: Manually Identified Stance | B10: Number Correct | C10: Total Manually Identified Entries | D10: Recall (%)
A11: Support | B11: {=SUMPRODUCT(('Hand Coded'!B$2:B$10000=A11)*(LOWER('Hand Coded'!B$2:B$10000)=LOWER(IFERROR(INDEX('gpt-5.4-mini'!F:F,MATCH('Hand Coded'!A$2:A$10000,'gpt-5.4-mini'!A:A,0)),""))))} -> 33 | C11: =COUNTIF('Hand Coded'!B:B,A11) -> 47 | D11: =IF(C11=0,"",B11/C11) -> 0.70212766
A12: Support with Changes | B12: {=SUMPRODUCT(('Hand Coded'!B$2:B$10000=A12)*(LOWER('Hand Coded'!B$2:B$10000)=LOWER(IFERROR(INDEX('gpt-5.4-mini'!F:F,MATCH('Hand Coded'!A$2:A$10000,'gpt-5.4-mini'!A:A,0)),""))))} -> 33 | C12: =COUNTIF('Hand Coded'!B:B,A12) -> 39 | D12: =IF(C12=0,"",B12/C12) -> 0.84615385
A13: Oppose | B13: {=SUMPRODUCT(('Hand Coded'!B$2:B$10000=A13)*(LOWER('Hand Coded'!B$2:B$10000)=LOWER(IFERROR(INDEX('gpt-5.4-mini'!F:F,MATCH('Hand Coded'!A$2:A$10000,'gpt-5.4-mini'!A:A,0)),""))))} -> 88 | C13: =COUNTIF('Hand Coded'!B:B,A13) -> 101 | D13: =IF(C13=0,"",B13/C13) -> 0.87128713
A14: Neutral | B14: {=SUMPRODUCT(('Hand Coded'!B$2:B$10000=A14)*(LOWER('Hand Coded'!B$2:B$10000)=LOWER(IFERROR(INDEX('gpt-5.4-mini'!F:F,MATCH('Hand Coded'!A$2:A$10000,'gpt-5.4-mini'!A:A,0)),""))))} -> 36 | C14: =COUNTIF('Hand Coded'!B:B,A14) -> 47 | D14: =IF(C14=0,"",B14/C14) -> 0.76595745
A15: Total | B15: =SUM(B11:B14) -> 190 | C15: =SUM(C11:C14) -> 234 | D15: =IF(C15=0,"",B15/C15) -> 0.81196581
A17: claude-sonnet-4-6
A18: Manually Identified Stance | B18: Number Correct | C18: Total Manually Identified Entries | D18: Recall (%)
A19: Support | B19: {=SUMPRODUCT(('Hand Coded'!B$2:B$10000=A19)*(LOWER('Hand Coded'!B$2:B$10000)=LOWER(IFERROR(INDEX('claude-sonnet-4-6'!F:F,MATCH('Hand Coded'!A$2:A$10000,'claude-sonnet-4-6'!A:A,0)),""))))} -> 39 | C19: =COUNTIF('Hand Coded'!B:B,A19) -> 47 | D19: =IF(C19=0,"",B19/C19) -> 0.82978723
A20: Support with Changes | B20: {=SUMPRODUCT(('Hand Coded'!B$2:B$10000=A20)*(LOWER('Hand Coded'!B$2:B$10000)=LOWER(IFERROR(INDEX('claude-sonnet-4-6'!F:F,MATCH('Hand Coded'!A$2:A$10000,'claude-sonnet-4-6'!A:A,0)),""))))} -> 36 | C20: =COUNTIF('Hand Coded'!B:B,A20) -> 39 | D20: =IF(C20=0,"",B20/C20) -> 0.92307692
A21: Oppose | B21: {=SUMPRODUCT(('Hand Coded'!B$2:B$10000=A21)*(LOWER('Hand Coded'!B$2:B$10000)=LOWER(IFERROR(INDEX('claude-sonnet-4-6'!F:F,MATCH('Hand Coded'!A$2:A$10000,'claude-sonnet-4-6'!A:A,0)),""))))} -> 93 | C21: =COUNTIF('Hand Coded'!B:B,A21) -> 101 | D21: =IF(C21=0,"",B21/C21) -> 0.92079208
A22: Neutral | B22: {=SUMPRODUCT(('Hand Coded'!B$2:B$10000=A22)*(LOWER('Hand Coded'!B$2:B$10000)=LOWER(IFERROR(INDEX('claude-sonnet-4-6'!F:F,MATCH('Hand Coded'!A$2:A$10000,'claude-sonnet-4-6'!A:A,0)),""))))} -> 29 | C22: =COUNTIF('Hand Coded'!B:B,A22) -> 47 | D22: =IF(C22=0,"",B22/C22) -> 0.61702128
A23: Total | B23: =SUM(B19:B22) -> 197 | C23: =SUM(C19:C22) -> 234 | D23: =IF(C23=0,"",B23/C23) -> 0.84188034

Sheet Disagreement Analysis
A1: pdf_id | B1: Hand Code | C1: Gemini | D1: GPT | E1: Claude | F1: 3 Models Agree? | G1: Hand = Consensus? | H1: All 3 Agree & Hand Differs | I1: Model Consensus Label | J1: Disagree Type | P1: SUMMARY STATISTICS | V1: FIELD SELECTOR:
A2: ='Hand Coded'!A2 -> 138 | B2: {=LOWER(TRIM(INDEX('Hand Coded'!A:G,ROW(),$W$11)))} -> support with changes | C2: {=IFERROR(LOWER(TRIM(INDEX('gemini-3.1-flash-lite-preview'!A:K,MATCH(A2,'gemini-3.1-flash-lite-preview'!A:A,0),$W$12))),"NOT FOUND")} -> support with changes | D2: {=IFERROR(LOWER(TRIM(INDEX('gpt-5.4-mini'!A:K,MATCH(A2,'gpt-5.4-mini'!A:A,0),$W$12))),"NOT FOUND")} -> support with changes | E2: {=IFERROR(LOWER(TRIM(INDEX('claude-sonnet-4-6'!A:K,MATCH(A2,'claude-sonnet-4-6'!A:A,0),$W$12))),"NOT FOUND")} -> support with changes | F2: =AND(C2=D2,D2=E2) -> TRUE | G2: =IF(F2,B2=C2,"N/A") -> TRUE | H2: =AND(F2,B2<>C2) -> FALSE | I2: =IF(F2,C2,"No consensus") -> support with changes | J2: =IF(H2,B2&" → "&I2,"") | P2: Total PDFs Analyzed | Q2: =COUNTA(A:A)-1 -> 234 | V2: Sentiment (llm_support_label) | W2: Hand Col # | X2: Model Col #
A3: ='Hand Coded'!A3 -> 241 | B3: {=LOWER(TRIM(INDEX('Hand Coded'!A:G,ROW(),$W$11)))} -> support with changes | C3: {=IFERROR(LOWER(TRIM(INDEX('gemini-3.1-flash-lite-preview'!A:K,MATCH(A3,'gemini-3.1-flash-lite-preview'!A:A,0),$W$12))),"NOT FOUND")} -> support with changes | D3: {=IFERROR(LOWER(TRIM(INDEX('gpt-5.4-mini'!A:K,MATCH(A3,'gpt-5.4-mini'!A:A,0),$W$12))),"NOT FOUND")} -> support with changes | E3: {=IFERROR(LOWER(TRIM(INDEX('claude-sonnet-4-6'!A:K,MATCH(A3,'claude-sonnet-4-6'!A:A,0),$W$12))),"NOT FOUND")} -> support with changes | F3: =AND(C3=D3,D3=E3) -> TRUE | G3: =IF(F3,B3=C3,"N/A") -> TRUE | H3: =AND(F3,B3<>C3) -> FALSE | I3: =IF(F3,C3,"No consensus") -> support with changes | J3: =IF(H3,B3&" → "&I3,"") | P3: Cases All 3 Models Agree | Q3: =COUNTIF(F:F,TRUE) -> 183 | R3: =Q3/Q2 -> 0.78205128 | V3: Sentiment (llm_support_label) | W3: 2 | X3: 6
A4: ='Hand Coded'!A4 -> 259 | B4: {=LOWER(TRIM(INDEX('Hand Coded'!A:G,ROW(),$W$11)))} -> neutral | C4: {=IFERROR(LOWER(TRIM(INDEX('gemini-3.1-flash-lite-preview'!A:K,MATCH(A4,'gemini-3.1-flash-lite-preview'!A:A,0),$W$12))),"NOT FOUND")} -> support | D4: {=IFERROR(LOWER(TRIM(INDEX('gpt-5.4-mini'!A:K,MATCH(A4,'gpt-5.4-mini'!A:A,0),$W$12))),"NOT FOUND")} -> support with changes | E4: {=IFERROR(LOWER(TRIM(INDEX('claude-sonnet-4-6'!A:K,MATCH(A4,'claude-sonnet-4-6'!A:A,0),$W$12))),"NOT FOUND")} -> support | F4: =AND(C4=D4,D4=E4) -> FALSE | G4: =IF(F4,B4=C4,"N/A") -> N/A | H4: =AND(F4,B4<>C4) -> FALSE | I4: =IF(F4,C4,"No consensus") -> No consensus | J4: =IF(H4,B4&" → "&I4,"") | P4: Hand Agrees with Consensus | Q4: =COUNTIF(G:G,TRUE) -> 172 | R4: =Q4/Q3 -> 0.93989071 | V4: Feedback Theme | W4: 3 | X4: 11
A5: ='Hand Coded'!A5 -> 264 | B5: {=LOWER(TRIM(INDEX('Hand Coded'!A:G,ROW(),$W$11)))} -> oppose | C5: {=IFERROR(LOWER(TRIM(INDEX('gemini-3.1-flash-lite-preview'!A:K,MATCH(A5,'gemini-3.1-flash-lite-preview'!A:A,0),$W$12))),"NOT FOUND")} -> support with changes | D5: {=IFERROR(LOWER(TRIM(INDEX('gpt-5.4-mini'!A:K,MATCH(A5,'gpt-5.4-mini'!A:A,0),$W$12))),"NOT FOUND")} -> oppose | E5: {=IFERROR(LOWER(TRIM(INDEX('claude-sonnet-4-6'!A:K,MATCH(A5,'claude-sonnet-4-6'!A:A,0),$W$12))),"NOT FOUND")} -> oppose | F5: =AND(C5=D5,D5=E5) -> FALSE | G5: =IF(F5,B5=C5,"N/A") -> N/A | H5: =AND(F5,B5<>C5) -> FALSE | I5: =IF(F5,C5,"No consensus") -> No consensus | J5: =IF(H5,B5&" → "&I5,"") | P5: All 3 Agree BUT Hand Disagrees | Q5: =COUNTIF(H:H,TRUE) -> 11 | R5: =Q5/Q2 -> 0.047008547 | V5: Project Type | W5: 4 | X5: 7
A6: ='Hand Coded'!A6 -> 273 | B6: {=LOWER(TRIM(INDEX('Hand Coded'!A:G,ROW(),$W$11)))} -> neutral | C6: {=IFERROR(LOWER(TRIM(INDEX('gemini-3.1-flash-lite-preview'!A:K,MATCH(A6,'gemini-3.1-flash-lite-preview'!A:A,0),$W$12))),"NOT FOUND")} -> neutral | D6: {=IFERROR(LOWER(TRIM(INDEX('gpt-5.4-mini'!A:K,MATCH(A6,'gpt-5.4-mini'!A:A,0),$W$12))),"NOT FOUND")} -> neutral | E6: {=IFERROR(LOWER(TRIM(INDEX('claude-sonnet-4-6'!A:K,MATCH(A6,'claude-sonnet-4-6'!A:A,0),$W$12))),"NOT FOUND")} -> support with changes | F6: =AND(C6=D6,D6=E6) -> FALSE | G6: =IF(F6,B6=C6,"N/A") -> N/A | H6: =AND(F6,B6<>C6) -> FALSE | I6: =IF(F6,C6,"No consensus") -> No consensus | J6: =IF(H6,B6&" → "&I6,"") | V6: Commenter Type | W6: 5 | X6: 8
A7: ='Hand Coded'!A7 -> 383 | B7: {=LOWER(TRIM(INDEX('Hand Coded'!A:G,ROW(),$W$11)))} -> support with changes | C7: {=IFERROR(LOWER(TRIM(INDEX('gemini-3.1-flash-lite-preview'!A:K,MATCH(A7,'gemini-3.1-flash-lite-preview'!A:A,0),$W$12))),"NOT FOUND")} -> support with changes | D7: {=IFERROR(LOWER(TRIM(INDEX('gpt-5.4-mini'!A:K,MATCH(A7,'gpt-5.4-mini'!A:A,0),$W$12))),"NOT FOUND")} -> support with changes | E7: {=IFERROR(LOWER(TRIM(INDEX('claude-sonnet-4-6'!A:K,MATCH(A7,'claude-sonnet-4-6'!A:A,0),$W$12))),"NOT FOUND")} -> support with changes | F7: =AND(C7=D7,D7=E7) -> TRUE | G7: =IF(F7,B7=C7,"N/A") -> TRUE | H7: =AND(F7,B7<>C7) -> FALSE | I7: =IF(F7,C7,"No consensus") -> support with changes | J7: =IF(H7,B7&" → "&I7,"") | P7: DISAGREEMENT DETAIL: Hand → Model Consensus | V7: Project State | W7: 6 | X7: 9
A8: ='Hand Coded'!A8 -> 416 | B8: {=LOWER(TRIM(INDEX('Hand Coded'!A:G,ROW(),$W$11)))} -> support with changes | C8: {=IFERROR(LOWER(TRIM(INDEX('gemini-3.1-flash-lite-preview'!A:K,MATCH(A8,'gemini-3.1-flash-lite-preview'!A:A,0),$W$12))),"NOT FOUND")} -> support with changes | D8: {=IFERROR(LOWER(TRIM(INDEX('gpt-5.4-mini'!A:K,MATCH(A8,'gpt-5.4-mini'!A:A,0),$W$12))),"NOT FOUND")} -> support with changes | E8: {=IFERROR(LOWER(TRIM(INDEX('claude-sonnet-4-6'!A:K,MATCH(A8,'claude-sonnet-4-6'!A:A,0),$W$12))),"NOT FOUND")} -> support with changes | F8: =AND(C8=D8,D8=E8) -> TRUE | G8: =IF(F8,B8=C8,"N/A") -> TRUE | H8: =AND(F8,B8<>C8) -> FALSE | I8: =IF(F8,C8,"No consensus") -> support with changes | J8: =IF(H8,B8&" → "&I8,"") | P8: Hand Value → Model Consensus | Q8: Count | R8: % of Disagreements | V8: Project Region | W8: 7 | X8: 10
A9: ='Hand Coded'!A9 -> 474 | B9: {=LOWER(TRIM(INDEX('Hand Coded'!A:G,ROW(),$W$11)))} -> neutral | C9: {=IFERROR(LOWER(TRIM(INDEX('gemini-3.1-flash-lite-preview'!A:K,MATCH(A9,'gemini-3.1-flash-lite-preview'!A:A,0),$W$12))),"NOT FOUND")} -> neutral | D9: {=IFERROR(LOWER(TRIM(INDEX('gpt-5.4-mini'!A:K,MATCH(A9,'gpt-5.4-mini'!A:A,0),$W$12))),"NOT FOUND")} -> neutral | E9: {=IFERROR(LOWER(TRIM(INDEX('claude-sonnet-4-6'!A:K,MATCH(A9,'claude-sonnet-4-6'!A:A,0),$W$12))),"NOT FOUND")} -> support | F9: =AND(C9=D9,D9=E9) -> FALSE | G9: =IF(F9,B9=C9,"N/A") -> N/A | H9: =AND(F9,B9<>C9) -> FALSE | I9: =IF(F9,C9,"No consensus") -> No consensus | J9: =IF(H9,B9&" → "&I9,"") | P9: {=IFERROR(INDEX(_xlfn._xlws.SORT(_xlfn.UNIQUE(_xlfn._xlws.FILTER($J$2:$J$5000,$J$2:$J$5000<>"")),1,1),ROW()-8),"")} -> neutral → oppose | Q9: =IF(P9="","",COUNTIF($J$2:$J$5000,P9)) -> 3 | R9: =IF(P9="","",Q9/$Q$5) -> 0.27272727
A10: ='Hand Coded'!A10 -> 516 | B10: {=LOWER(TRIM(INDEX('Hand Coded'!A:G,ROW(),$W$11)))} -> support with changes | C10: {=IFERROR(LOWER(TRIM(INDEX('gemini-3.1-flash-lite-preview'!A:K,MATCH(A10,'gemini-3.1-flash-lite-preview'!A:A,0),$W$12))),"NOT FOUND")} -> support with changes | D10: {=IFERROR(LOWER(TRIM(INDEX('gpt-5.4-mini'!A:K,MATCH(A10,'gpt-5.4-mini'!A:A,0),$W$12))),"NOT FOUND")} -> support with changes | E10: {=IFERROR(LOWER(TRIM(INDEX('claude-sonnet-4-6'!A:K,MATCH(A10,'claude-sonnet-4-6'!A:A,0),$W$12))),"NOT FOUND")} -> support with changes | F10: =AND(C10=D10,D10=E10) -> TRUE | G10: =IF(F10,B10=C10,"N/A") -> TRUE | H10: =AND(F10,B10<>C10) -> FALSE | I10: =IF(F10,C10,"No consensus") -> support with changes | J10: =IF(H10,B10&" → "&I10,"") | P10: {=IFERROR(INDEX(_xlfn._xlws.SORT(_xlfn.UNIQUE(_xlfn._xlws.FILTER($J$2:$J$5000,$J$2:$J$5000<>"")),1,1),ROW()-8),"")} -> neutral → support with changes | Q10: =IF(P10="","",COUNTIF($J$2:$J$5000,P10)) -> 1 | R10: =IF(P10="","",Q10/$Q$5) -> 0.090909091 | V10: Resolved (auto)
A11: ='Hand Coded'!A11 -> 729 | B11: {=LOWER(TRIM(INDEX('Hand Coded'!A:G,ROW(),$W$11)))} -> neutral | C11: {=IFERROR(LOWER(TRIM(INDEX('gemini-3.1-flash-lite-preview'!A:K,MATCH(A11,'gemini-3.1-flash-lite-preview'!A:A,0),$W$12))),"NOT FOUND")} -> neutral | D11: {=IFERROR(LOWER(TRIM(INDEX('gpt-5.4-mini'!A:K,MATCH(A11,'gpt-5.4-mini'!A:A,0),$W$12))),"NOT FOUND")} -> neutral | E11: {=IFERROR(LOWER(TRIM(INDEX('claude-sonnet-4-6'!A:K,MATCH(A11,'claude-sonnet-4-6'!A:A,0),$W$12))),"NOT FOUND")} -> neutral | F11: =AND(C11=D11,D11=E11) -> TRUE | G11: =IF(F11,B11=C11,"N/A") -> TRUE | H11: =AND(F11,B11<>C11) -> FALSE | I11: =IF(F11,C11,"No consensus") -> neutral | J11: =IF(H11,B11&" → "&I11,"") | P11: {=IFERROR(INDEX(_xlfn._xlws.SORT(_xlfn.UNIQUE(_xlfn._xlws.FILTER($J$2:$J$5000,$J$2:$J$5000<>"")),1,1),ROW()-8),"")} -> oppose → neutral | Q11: =IF(P11="","",COUNTIF($J$2:$J$5000,P11)) -> 1 | R11: =IF(P11="","",Q11/$Q$5) -> 0.090909091 | V11: Hand Col # | W11: =_xlfn.XLOOKUP($V$2,$V$3:$V$8,W3:W8) -> 2
A12: ='Hand Coded'!A12 -> 761 | B12: {=LOWER(TRIM(INDEX('Hand Coded'!A:G,ROW(),$W$11)))} -> support | C12: {=IFERROR(LOWER(TRIM(INDEX('gemini-3.1-flash-lite-preview'!A:K,MATCH(A12,'gemini-3.1-flash-lite-preview'!A:A,0),$W$12))),"NOT FOUND")} -> support | D12: {=IFERROR(LOWER(TRIM(INDEX('gpt-5.4-mini'!A:K,MATCH(A12,'gpt-5.4-mini'!A:A,0),$W$12))),"NOT FOUND")} -> support | E12: {=IFERROR(LOWER(TRIM(INDEX('claude-sonnet-4-6'!A:K,MATCH(A12,'claude-sonnet-4-6'!A:A,0),$W$12))),"NOT FOUND")} -> support | F12: =AND(C12=D12,D12=E12) -> TRUE | G12: =IF(F12,B12=C12,"N/A") -> TRUE | H12: =AND(F12,B12<>C12) -> FALSE | I12: =IF(F12,C12,"No consensus") -> support | J12: =IF(H12,B12&" → "&I12,"") | P12: {=IFERROR(INDEX(_xlfn._xlws.SORT(_xlfn.UNIQUE(_xlfn._xlws.FILTER($J$2:$J$5000,$J$2:$J$5000<>"")),1,1),ROW()-8),"")} -> oppose → support with changes | Q12: =IF(P12="","",COUNTIF($J$2:$J$5000,P12)) -> 2 | R12: =IF(P12="","",Q12/$Q$5) -> 0.18181818 | V12: Model Col # | W12: =_xlfn.XLOOKUP($V$2,$V$3:$V$8,X3:X8) -> 6
A13: ='Hand Coded'!A13 -> 779 | B13: {=LOWER(TRIM(INDEX('Hand Coded'!A:G,ROW(),$W$11)))} -> oppose | C13: {=IFERROR(LOWER(TRIM(INDEX('gemini-3.1-flash-lite-preview'!A:K,MATCH(A13,'gemini-3.1-flash-lite-preview'!A:A,0),$W$12))),"NOT FOUND")} -> oppose | D13: {=IFERROR(LOWER(TRIM(INDEX('gpt-5.4-mini'!A:K,MATCH(A13,'gpt-5.4-mini'!A:A,0),$W$12))),"NOT FOUND")} -> oppose | E13: {=IFERROR(LOWER(TRIM(INDEX('claude-sonnet-4-6'!A:K,MATCH(A13,'claude-sonnet-4-6'!A:A,0),$W$12))),"NOT FOUND")} -> oppose | F13: =AND(C13=D13,D13=E13) -> TRUE | G13: =IF(F13,B13=C13,"N/A") -> TRUE | H13: =AND(F13,B13<>C13) -> FALSE | I13: =IF(F13,C13,"No consensus") -> oppose | J13: =IF(H13,B13&" → "&I13,"") | P13: {=IFERROR(INDEX(_xlfn._xlws.SORT(_xlfn.UNIQUE(_xlfn._xlws.FILTER($J$2:$J$5000,$J$2:$J$5000<>"")),1,1),ROW()-8),"")} -> support → neutral | Q13: =IF(P13="","",COUNTIF($J$2:$J$5000,P13)) -> 1 | R13: =IF(P13="","",Q13/$Q$5) -> 0.090909091
A14: ='Hand Coded'!A14 -> 837 | B14: {=LOWER(TRIM(INDEX('Hand Coded'!A:G,ROW(),$W$11)))} -> neutral | C14: {=IFERROR(LOWER(TRIM(INDEX('gemini-3.1-flash-lite-preview'!A:K,MATCH(A14,'gemini-3.1-flash-lite-preview'!A:A,0),$W$12))),"NOT FOUND")} -> support with changes | D14: {=IFERROR(LOWER(TRIM(INDEX('gpt-5.4-mini'!A:K,MATCH(A14,'gpt-5.4-mini'!A:A,0),$W$12))),"NOT FOUND")} -> neutral | E14: {=IFERROR(LOWER(TRIM(INDEX('claude-sonnet-4-6'!A:K,MATCH(A14,'claude-sonnet-4-6'!A:A,0),$W$12))),"NOT FOUND")} -> neutral | F14: =AND(C14=D14,D14=E14) -> FALSE | G14: =IF(F14,B14=C14,"N/A") -> N/A | H14: =AND(F14,B14<>C14) -> FALSE | I14: =IF(F14,C14,"No consensus") -> No consensus | J14: =IF(H14,B14&" → "&I14,"") | P14: {=IFERROR(INDEX(_xlfn._xlws.SORT(_xlfn.UNIQUE(_xlfn._xlws.FILTER($J$2:$J$5000,$J$2:$J$5000<>"")),1,1),ROW()-8),"")} -> support → oppose | Q14: =IF(P14="","",COUNTIF($J$2:$J$5000,P14)) -> 1 | R14: =IF(P14="","",Q14/$Q$5) -> 0.090909091
A15: ='Hand Coded'!A15 -> 877 | B15: {=LOWER(TRIM(INDEX('Hand Coded'!A:G,ROW(),$W$11)))} -> neutral | C15: {=IFERROR(LOWER(TRIM(INDEX('gemini-3.1-flash-lite-preview'!A:K,MATCH(A15,'gemini-3.1-flash-lite-preview'!A:A,0),$W$12))),"NOT FOUND")} -> neutral | D15: {=IFERROR(LOWER(TRIM(INDEX('gpt-5.4-mini'!A:K,MATCH(A15,'gpt-5.4-mini'!A:A,0),$W$12))),"NOT FOUND")} -> neutral | E15: {=IFERROR(LOWER(TRIM(INDEX('claude-sonnet-4-6'!A:K,MATCH(A15,'claude-sonnet-4-6'!A:A,0),$W$12))),"NOT FOUND")} -> neutral | F15: =AND(C15=D15,D15=E15) -> TRUE | G15: =IF(F15,B15=C15,"N/A") -> TRUE | H15: =AND(F15,B15<>C15) -> FALSE | I15: =IF(F15,C15,"No consensus") -> neutral | J15: =IF(H15,B15&" → "&I15,"") | P15: {=IFERROR(INDEX(_xlfn._xlws.SORT(_xlfn.UNIQUE(_xlfn._xlws.FILTER($J$2:$J$5000,$J$2:$J$5000<>"")),1,1),ROW()-8),"")} -> support → support with changes | Q15: =IF(P15="","",COUNTIF($J$2:$J$5000,P15)) -> 2 | R15: =IF(P15="","",Q15/$Q$5) -> 0.18181818
A16: ='Hand Coded'!A16 -> 896 | B16: {=LOWER(TRIM(INDEX('Hand Coded'!A:G,ROW(),$W$11)))} -> neutral | C16: {=IFERROR(LOWER(TRIM(INDEX('gemini-3.1-flash-lite-preview'!A:K,MATCH(A16,'gemini-3.1-flash-lite-preview'!A:A,0),$W$12))),"NOT FOUND")} -> oppose | D16: {=IFERROR(LOWER(TRIM(INDEX('gpt-5.4-mini'!A:K,MATCH(A16,'gpt-5.4-mini'!A:A,0),$W$12))),"NOT FOUND")} -> neutral | E16: {=IFERROR(LOWER(TRIM(INDEX('claude-sonnet-4-6'!A:K,MATCH(A16,'claude-sonnet-4-6'!A:A,0),$W$12))),"NOT FOUND")} -> support | F16: =AND(C16=D16,D16=E16) -> FALSE | G16: =IF(F16,B16=C16,"N/A") -> N/A | H16: =AND(F16,B16<>C16) -> FALSE | I16: =IF(F16,C16,"No consensus") -> No consensus | J16: =IF(H16,B16&" → "&I16,"") | P16: {=IFERROR(INDEX(_xlfn._xlws.SORT(_xlfn.UNIQUE(_xlfn._xlws.FILTER($J$2:$J$5000,$J$2:$J$5000<>"")),1,1),ROW()-8),"")} | Q16: =IF(P16="","",COUNTIF($J$2:$J$5000,P16)) | R16: =IF(P16="","",Q16/$Q$5)
A17: ='Hand Coded'!A17 -> 923 | B17: {=LOWER(TRIM(INDEX('Hand Coded'!A:G,ROW(),$W$11)))} -> oppose | C17: {=IFERROR(LOWER(TRIM(INDEX('gemini-3.1-flash-lite-preview'!A:K,MATCH(A17,'gemini-3.1-flash-lite-preview'!A:A,0),$W$12))),"NOT FOUND")} -> oppose | D17: {=IFERROR(LOWER(TRIM(INDEX('gpt-5.4-mini'!A:K,MATCH(A17,'gpt-5.4-mini'!A:A,0),$W$12))),"NOT FOUND")} -> oppose | E17: {=IFERROR(LOWER(TRIM(INDEX('claude-sonnet-4-6'!A:K,MATCH(A17,'claude-sonnet-4-6'!A:A,0),$W$12))),"NOT FOUND")} -> oppose | F17: =AND(C17=D17,D17=E17) -> TRUE | G17: =IF(F17,B17=C17,"N/A") -> TRUE | H17: =AND(F17,B17<>C17) -> FALSE | I17: =IF(F17,C17,"No consensus") -> oppose | J17: =IF(H17,B17&" → "&I17,"") | P17: {=IFERROR(INDEX(_xlfn._xlws.SORT(_xlfn.UNIQUE(_xlfn._xlws.FILTER($J$2:$J$5000,$J$2:$J$5000<>"")),1,1),ROW()-8),"")} | Q17: =IF(P17="","",COUNTIF($J$2:$J$5000,P17)) | R17: =IF(P17="","",Q17/$Q$5)
A18: ='Hand Coded'!A18 -> 940 | B18: {=LOWER(TRIM(INDEX('Hand Coded'!A:G,ROW(),$W$11)))} -> oppose | C18: {=IFERROR(LOWER(TRIM(INDEX('gemini-3.1-flash-lite-preview'!A:K,MATCH(A18,'gemini-3.1-flash-lite-preview'!A:A,0),$W$12))),"NOT FOUND")} -> oppose | D18: {=IFERROR(LOWER(TRIM(INDEX('gpt-5.4-mini'!A:K,MATCH(A18,'gpt-5.4-mini'!A:A,0),$W$12))),"NOT FOUND")} -> oppose | E18: {=IFERROR(LOWER(TRIM(INDEX('claude-sonnet-4-6'!A:K,MATCH(A18,'claude-sonnet-4-6'!A:A,0),$W$12))),"NOT FOUND")} -> oppose | F18: =AND(C18=D18,D18=E18) -> TRUE | G18: =IF(F18,B18=C18,"N/A") -> TRUE | H18: =AND(F18,B18<>C18) -> FALSE | I18: =IF(F18,C18,"No consensus") -> oppose | J18: =IF(H18,B18&" → "&I18,"") | P18: {=IFERROR(INDEX(_xlfn._xlws.SORT(_xlfn.UNIQUE(_xlfn._xlws.FILTER($J$2:$J$5000,$J$2:$J$5000<>"")),1,1),ROW()-8),"")} | Q18: =IF(P18="","",COUNTIF($J$2:$J$5000,P18)) | R18: =IF(P18="","",Q18/$Q$5)
A19: ='Hand Coded'!A19 -> 951 | B19: {=LOWER(TRIM(INDEX('Hand Coded'!A:G,ROW(),$W$11)))} -> oppose | C19: {=IFERROR(LOWER(TRIM(INDEX('gemini-3.1-flash-lite-preview'!A:K,MATCH(A19,'gemini-3.1-flash-lite-preview'!A:A,0),$W$12))),"NOT FOUND")} -> oppose | D19: {=IFERROR(LOWER(TRIM(INDEX('gpt-5.4-mini'!A:K,MATCH(A19,'gpt-5.4-mini'!A:A,0),$W$12))),"NOT FOUND")} -> oppose | E19: {=IFERROR(LOWER(TRIM(INDEX('claude-sonnet-4-6'!A:K,MATCH(A19,'claude-sonnet-4-6'!A:A,0),$W$12))),"NOT FOUND")} -> oppose | F19: =AND(C19=D19,D19=E19) -> TRUE | G19: =IF(F19,B19=C19,"N/A") -> TRUE | H19: =AND(F19,B19<>C19) -> FALSE | I19: =IF(F19,C19,"No consensus") -> oppose | J19: =IF(H19,B19&" → "&I19,"")
A20: ='Hand Coded'!A20 -> 987 | B20: {=LOWER(TRIM(INDEX('Hand Coded'!A:G,ROW(),$W$11)))} -> support with changes | C20: {=IFERROR(LOWER(TRIM(INDEX('gemini-3.1-flash-lite-preview'!A:K,MATCH(A20,'gemini-3.1-flash-lite-preview'!A:A,0),$W$12))),"NOT FOUND")} -> support with changes | D20: {=IFERROR(LOWER(TRIM(INDEX('gpt-5.4-mini'!A:K,MATCH(A20,'gpt-5.4-mini'!A:A,0),$W$12))),"NOT FOUND")} -> support with changes | E20: {=IFERROR(LOWER(TRIM(INDEX('claude-sonnet-4-6'!A:K,MATCH(A20,'claude-sonnet-4-6'!A:A,0),$W$12))),"NOT FOUND")} -> support with changes | F20: =AND(C20=D20,D20=E20) -> TRUE | G20: =IF(F20,B20=C20,"N/A") -> TRUE | H20: =AND(F20,B20<>C20) -> FALSE | I20: =IF(F20,C20,"No consensus") -> support with changes | J20: =IF(H20,B20&" → "&I20,"")
A21: ='Hand Coded'!A21 -> 1010 | B21: {=LOWER(TRIM(INDEX('Hand Coded'!A:G,ROW(),$W$11)))} -> neutral | C21: {=IFERROR(LOWER(TRIM(INDEX('gemini-3.1-flash-lite-preview'!A:K,MATCH(A21,'gemini-3.1-flash-lite-preview'!A:A,0),$W$12))),"NOT FOUND")} -> neutral | D21: {=IFERROR(LOWER(TRIM(INDEX('gpt-5.4-mini'!A:K,MATCH(A21,'gpt-5.4-mini'!A:A,0),$W$12))),"NOT FOUND")} -> neutral | E21: {=IFERROR(LOWER(TRIM(INDEX('claude-sonnet-4-6'!A:K,MATCH(A21,'claude-sonnet-4-6'!A:A,0),$W$12))),"NOT FOUND")} -> neutral | F21: =AND(C21=D21,D21=E21) -> TRUE | G21: =IF(F21,B21=C21,"N/A") -> TRUE | H21: =AND(F21,B21<>C21) -> FALSE | I21: =IF(F21,C21,"No consensus") -> neutral | J21: =IF(H21,B21&" → "&I21,"")
A22: ='Hand Coded'!A22 -> 1058 | B22: {=LOWER(TRIM(INDEX('Hand Coded'!A:G,ROW(),$W$11)))} -> oppose | C22: {=IFERROR(LOWER(TRIM(INDEX('gemini-3.1-flash-lite-preview'!A:K,MATCH(A22,'gemini-3.1-flash-lite-preview'!A:A,0),$W$12))),"NOT FOUND")} -> oppose | D22: {=IFERROR(LOWER(TRIM(INDEX('gpt-5.4-mini'!A:K,MATCH(A22,'gpt-5.4-mini'!A:A,0),$W$12))),"NOT FOUND")} -> oppose | E22: {=IFERROR(LOWER(TRIM(INDEX('claude-sonnet-4-6'!A:K,MATCH(A22,'claude-sonnet-4-6'!A:A,0),$W$12))),"NOT FOUND")} -> oppose | F22: =AND(C22=D22,D22=E22) -> TRUE | G22: =IF(F22,B22=C22,"N/A") -> TRUE | H22: =AND(F22,B22<>C22) -> FALSE | I22: =IF(F22,C22,"No consensus") -> oppose | J22: =IF(H22,B22&" → "&I22,"")
